Workbook

Sheet README
A1: 서울 웨딩홀 마스터북 v2 (지도 보이게 / 플래너형)
A3: 이번 버전은 사용자가 요청한 두 가지를 반영했습니다:
A4: 1) Map_View 시트에 웨딩홀 위치가 '바로 보이는' 점 지도형 뷰 추가
A5: 2) Starter Set을 60개까지 확장하고, 웨딩 플래너식 관리 컬럼(계약금, 연출료, 꽃장식, 잔금시점, 주차, 예식간격 등) 추가
A7: 중요 고지
A8: - 지도는 실제 GIS/네이버 지도 API 임베드가 아니라, 서울 구 단위 중심좌표 기반의 내부 시각화입니다.
A9: - 즉, 각 웨딩홀의 '정확한 건물 좌표'가 아니라 '구 단위 위치감'을 빠르게 보는 용도입니다.
A10: - 공식 홈페이지는 확인된 경우만 입력했고, 미확인 항목은 공란으로 두었습니다.
A11: - 가격/계약금/식대는 웨딩홀·일자·시간대·프로모션에 따라 달라지므로 반드시 최종 상담 시 재확인해야 합니다.
A13: 권장 사용 흐름
A14: 1. Master_60에서 후보들을 비교
A15: 2. Shortlist에 최종 후보 10~15곳만 복사
... A17: 4. Map_View에서 지역 분포 확인

Sheet Dashboard
A1: 서울 웨딩홀 대시보드
A3: 핵심 KPI | D3: 실무 체크
A4: 총 행 수 | B4: =COUNTA(Master_60!B2:B46) -> 45 | D4: 예상총비용 = 식대평균 × 최소보증 + 대관료 + 연출료 + 꽃장식
A5: 공식 링크 입력 수 | B5: =COUNTIF(Master_60!V2:V46,"<>") -> 45 | D5: 계약금(가이드) = 예상총비용의 10%
A6: 식대 시작가 입력 수 | B6: =COUNTIF(Master_60!K2:K46,">0") -> 0 | D6: 계약금(실제확인)은 공식 FAQ/상담자료 확인 시만 입력
A7: 계약금 실제 확인 수 | B7: =COUNTIF(Master_60!S2:S46,">0") -> 5 | D7: Map_View는 구 단위 위치감 용도
A8: 평균 식대 평균 | B8: =IFERROR(AVERAGE(Master_60!L2:L46),0) -> 96015.556
A9: 평균 최소보증 | B9: =IFERROR(AVERAGE(Master_60!N2:N46),0) -> 96051.515 | D9: 새 기능
A10: 평균 예상총비용 | B10: =IFERROR(AVERAGE(Master_60!Z2:Z46),0) -> 0 | D10: 홀톤(밝은/어두운/혼합) 필터
A11: 미확인 링크 수 | B11: =COUNTIF(Master_60!W2:W46,"미확인") -> 0 | D11: 강남권/비강남권 분류
D12: 교통·가성비·검증 점수
D13: 취향적합도/부모님선호 수기 입력
D14: 추천점수 / 추천등급 자동 산출
D15: 예산 시뮬레이터 시트 추가

Sheet Master_60
A1: ID | B1: 웨딩홀 이름 | C1: 구 | D1: 주소 | E1: 도시 | F1: 홀타입 | G1: 홀톤(밝은/어두운/혼합) | H1: 예식형태 | I1: 예식간격(분) | J1: 홀수 | K1: 메뉴 | L1: 식대 시작가(원) | M1: 식대 평균가(원) | N1: 식대 범위 | O1: 최소보증인원 | P1: 최대수용인원 | Q1: 대관료(원) | R1: 최소 대관료(원) | S1: 연출료(원) | T1: 꽃장식(원) | U1: 계약금(실제확인) | V1: 계약금 가이드(10%) | W1: 공식 홈페이지 | X1: 링크 검증 | Y1: 네이버지도 | Z1: 주차 | AA1: 무료주차 | AB1: 잔금시점 | AC1: 지하철/접근 | AD1: 예상 총비용(원) | AE1: 데이터완성도 | AF1: Source | AG1: MapX | AH1: MapY | AI1: 메모 | AJ1: 강남권여부 | AK1: 권역 | AL1: 분위기태그 | AM1: 교통점수(1-5) | AN1: 가성비점수(1-5) | AO1: 최소보증점수(1-5) | AP1: 검증점수(1-5) | AQ1: 취향적합도(1-5) | AR1: 부모님선호(1-5) | AS1: 추천점수 | AT1: 추천등급 | AU1: 예산밴드 | AV1: 비고_플래너
A2: 1 | B2: 아펠가모 광화문 | C2: 종로구 | D2: 서울 종로구 종로1길 50 | E2: 서울특별시 | F2: 컨벤션 | G2: 밝은홀 | H2: 분리 | I2: 90 | J2: 1 | K2: 뷔페 | L2: 85000 | M2: 110000 | N2: 85000~110000 | O2: 300 | P2: 550 | Q2: 6500000 | V2: =IF(AND(T2="",AB2>0),ROUND(AB2*10%,-4),T2) -> 0 | W2: https://apelgamo.com/home/wedding3 | X2: 확인 | Y2: https://map.naver.com/v5/search/아펠가모%20광화문 | Z2: 주차가능 | AC2: =IF(AND(L2>0,N2>0),L2*N2+IF(P2="",0,P2)+IF(Q2="",0,Q2)+IF(S2="",0,S2),"") -> #VALUE! | AD2: =IF(COUNTA(B2:AB2)=0,"",COUNTA(B2:AB2)-COUNTBLANK(B2:AB2)) -> 15 | AF2: https://apelgamo.com/home/wedding3 | AG2: 53.8 | AH2: 63.8 | AI2: 공식 페이지 / 식대는 플랫폼 참고 | AJ2: =IF(OR(C2="강남구",C2="서초구",C2="송파구"),"강남권","비강남권") -> 비강남권 | AK2: =IF(C2="강남구","강남",IF(C2="서초구","서초",IF(C2="송파구","송파",IF(C2="영등포구","영등포",IF(C2="마포구","마포","기타"))))) -> 기타 | AL2: 채플감성/단정 | AM2: 1 | AN2: =IF(M2="","",IF(M2<=70000,5,IF(M2<=85000,4,IF(M2<=100000,3,IF(M2<=120000,2,1))))) -> 2 | AO2: =IF(O2="","",IF(O2<=150,5,IF(O2<=200,4,IF(O2<=250,3,IF(O2<=300,2,1))))) -> 2 | AP2: =IF(B2="","",IF(AND(X2="확인",U2>0),5,IF(X2="확인",4,IF(AE2<>"",2,1)))) -> 4 | AQ2: 4 | AR2: 4 | AS2: =IF(B2="","",ROUND(AN2*Assumptions!$B$3+AO2*Assumptions!$B$4+AM2*Assumptions!$B$5+AP2*Assumptions!$B$6+AQ2*Assumptions!$B$7+AR2*Assumptions!$B$8,2)) -> 2.85 | AT2: =IF(AS2="","",IF(AS2>=4.2,"A",IF(AS2>=3.4,"B","C"))) -> C | AU2: =IF(AD2="","",IF(AD2<=25000000,"~2.5억",IF(AD2<=35000000,"2.5~3.5억",IF(AD2<=50000000,"3.5~5억","5억+")))) -> ~2.5억
A3: 2 | B3: HW컨벤션센터 | C3: 종로구 | D3: 서울 종로구 자하문로 255 | E3: 서울특별시 | F3: 컨벤션 | G3: 혼합 | H3: 분리 | I3: 120 | J3: 3 | K3: 뷔페 | L3: 130000 | M3: 109000 | N3: 89000~130000 | O3: 200 | P3: 800 | Q3: 17000000 | R3: 13000000 | S3: - | T3: - | U3: - | V3: =IF(AND(T3="",AB3>0),ROUND(AB3*10%,-4),T3) -> - | X3: 미확인 | Y3: https://map.naver.com/v5/search/HW컨벤션센터 | AC3: =IF(AND(L3>0,N3>0),L3*N3+IF(P3="",0,P3)+IF(Q3="",0,Q3)+IF(S3="",0,S3),"") -> #VALUE! | AD3: =IF(COUNTA(B3:AB3)=0,"",COUNTA(B3:AB3)-COUNTBLANK(B3:AB3)) -> 19 | AG3: 54.6 | AH3: 63.8 | AI3: 주소만 반영 | AJ3: =IF(OR(C3="강남구",C3="서초구",C3="송파구"),"강남권","비강남권") -> 비강남권 | AK3: =IF(C3="강남구","강남",IF(C3="서초구","서초",IF(C3="송파구","송파",IF(C3="영등포구","영등포",IF(C3="마포구","마포","기타"))))) -> 기타 | AM3: =IF(B3="","",MIN(5,IF(ISNUMBER(SEARCH("역",AC3)),4,IF(AC3<>"",3,2))+IF(Z3<>"",1,0))) -> #VALUE! | AN3: =IF(M3="","",IF(M3<=70000,5,IF(M3<=85000,4,IF(M3<=100000,3,IF(M3<=120000,2,1))))) -> 2 | AO3: =IF(O3="","",IF(O3<=150,5,IF(O3<=200,4,IF(O3<=250,3,IF(O3<=300,2,1))))) -> 4 | AP3: =IF(B3="","",IF(AND(X3="확인",U3>0),5,IF(X3="확인",4,IF(AE3<>"",2,1)))) -> 1 | AQ3: 3 | AR3: 3 | AS3: =IF(B3="","",ROUND(AN3*Assumptions!$B$3+AO3*Assumptions!$B$4+AM3*Assumptions!$B$5+AP3*Assumptions!$B$6+AQ3*Assumptions!$B$7+AR3*Assumptions!$B$8,2)) -> #VALUE! | AT3: =IF(AS3="","",IF(AS3>=4.2,"A",IF(AS3>=3.4,"B","C"))) -> #VALUE! | AU3: =IF(AD3="","",IF(AD3<=25000000,"~2.5억",IF(AD3<=35000000,"2.5~3.5억",IF(AD3<=50000000,"3.5~5억","5억+")))) -> ~2.5억
A4: 5 | B4: 성균관컨벤션웨딩홀 | C4: 종로구 | D4: 서울 종로구 성균관로 31 | E4: 서울특별시 | F4: 컨벤션 | G4: 어두운홀 | H4: 분리 | I4: 90 | J4: 1 | K4: 뷔페 | L4: 75000 | M4: 75000 | N4: 75000 | O4: 200 | P4: 500 | Q4: 8350000 | R4: - | S4: - | T4: - | U4: - | V4: =IF(AND(T4="",AB4>0),ROUND(AB4*10%,-4),T4) -> - | X4: 미확인 | Y4: https://map.naver.com/v5/search/성균관컨벤션웨딩홀 | AC4: =IF(AND(L4>0,N4>0),L4*N4+IF(P4="",0,P4)+IF(Q4="",0,Q4)+IF(S4="",0,S4),"") -> #VALUE! | AD4: =IF(COUNTA(B4:AB4)=0,"",COUNTA(B4:AB4)-COUNTBLANK(B4:AB4)) -> 19 | AG4: 53.8 | AH4: 64.6 | AI4: 주소만 반영 | AJ4: =IF(OR(C4="강남구",C4="서초구",C4="송파구"),"강남권","비강남권") -> 비강남권 | AK4: =IF(C4="강남구","강남",IF(C4="서초구","서초",IF(C4="송파구","송파",IF(C4="영등포구","영등포",IF(C4="마포구","마포","기타"))))) -> 기타 | AM4: =IF(B4="","",MIN(5,IF(ISNUMBER(SEARCH("역",AC4)),4,IF(AC4<>"",3,2))+IF(Z4<>"",1,0))) -> #VALUE! | AN4: =IF(M4="","",IF(M4<=70000,5,IF(M4<=85000,4,IF(M4<=100000,3,IF(M4<=120000,2,1))))) -> 4 | AO4: =IF(O4="","",IF(O4<=150,5,IF(O4<=200,4,IF(O4<=250,3,IF(O4<=300,2,1))))) -> 4 | AP4: =IF(B4="","",IF(AND(X4="확인",U4>0),5,IF(X4="확인",4,IF(AE4<>"",2,1)))) -> 1 | AQ4: 3 | AR4: 3 | AS4: =IF(B4="","",ROUND(AN4*Assumptions!$B$3+AO4*Assumptions!$B$4+AM4*Assumptions!$B$5+AP4*Assumptions!$B$6+AQ4*Assumptions!$B$7+AR4*Assumptions!$B$8,2)) -> #VALUE! | AT4: =IF(AS4="","",IF(AS4>=4.2,"A",IF(AS4>=3.4,"B","C"))) -> #VALUE! | AU4: =IF(AD4="","",IF(AD4<=25000000,"~2.5억",IF(AD4<=35000000,"2.5~3.5억",IF(AD4<=50000000,"3.5~5억","5억+")))) -> ~2.5억
A5: 6 | B5: SW컨벤션센터 | C5: 종로구 | D5: 서울 종로구 지봉로 19 | E5: 서울특별시 | F5: 컨벤션 | G5: 어두운홀 | H5: 분리 | I5: 70 | J5: 1 | K5: 뷔페 | L5: 70000 | M5: 70000 | N5: 70000 | O5: 200 | P5: 800 | Q5: 6000000 | R5: - | S5: - | T5: - | U5: - | V5: =IF(AND(T5="",AB5>0),ROUND(AB5*10%,-4),T5) -> - | X5: 미확인 | Y5: https://map.naver.com/v5/search/SW컨벤션센터 | AC5: =IF(AND(L5>0,N5>0),L5*N5+IF(P5="",0,P5)+IF(Q5="",0,Q5)+IF(S5="",0,S5),"") -> #VALUE! | AD5: =IF(COUNTA(B5:AB5)=0,"",COUNTA(B5:AB5)-COUNTBLANK(B5:AB5)) -> 19 | AG5: 54.6 | AH5: 64.6 | AI5: 주소만 반영 | AJ5: =IF(OR(C5="강남구",C5="서초구",C5="송파구"),"강남권","비강남권") -> 비강남권 | AK5: =IF(C5="강남구","강남",IF(C5="서초구","서초",IF(C5="송파구","송파",IF(C5="영등포구","영등포",IF(C5="마포구","마포","기타"))))) -> 기타 | AM5: =IF(B5="","",MIN(5,IF(ISNUMBER(SEARCH("역",AC5)),4,IF(AC5<>"",3,2))+IF(Z5<>"",1,0))) -> #VALUE! | AN5: =IF(M5="","",IF(M5<=70000,5,IF(M5<=85000,4,IF(M5<=100000,3,IF(M5<=120000,2,1))))) -> 5 | AO5: =IF(O5="","",IF(O5<=150,5,IF(O5<=200,4,IF(O5<=250,3,IF(O5<=300,2,1))))) -> 4 | AP5: =IF(B5="","",IF(AND(X5="확인",U5>0),5,IF(X5="확인",4,IF(AE5<>"",2,1)))) -> 1 | AQ5: 3 | AR5: 3 | AS5: =IF(B5="","",ROUND(AN5*Assumptions!$B$3+AO5*Assumptions!$B$4+AM5*Assumptions!$B$5+AP5*Assumptions!$B$6+AQ5*Assumptions!$B$7+AR5*Assumptions!$B$8,2)) -> #VALUE! | AT5: =IF(AS5="","",IF(AS5>=4.2,"A",IF(AS5>=3.4,"B","C"))) -> #VALUE! | AU5: =IF(AD5="","",IF(AD5<=25000000,"~2.5억",IF(AD5<=35000000,"2.5~3.5억",IF(AD5<=50000000,"3.5~5억","5억+")))) -> ~2.5억
A6: 8 | B6: 라루체 | C6: 중구 | D6: 서울 중구 퇴계로18길 46 | E6: 서울특별시 | F6: 하우스 | G6: 밝은홀 | H6: 분리 | I6: 120 | J6: 2 | K6: 뷔페 | L6: 110000 | M6: 110000 | N6: 110000 | O6: 200 | P6: 1500 | Q6: 15000000 | R6: - | S6: - | T6: - | U6: - | V6: =IF(AND(T6="",AB6>0),ROUND(AB6*10%,-4),T6) -> - | W6: https://www.lalucewedding.co.kr/ | X6: 확인 | Y6: https://map.naver.com/v5/search/라루체 | Z6: 주차가능 | AC6: =IF(AND(L6>0,N6>0),L6*N6+IF(P6="",0,P6)+IF(Q6="",0,Q6)+IF(S6="",0,S6),"") -> #VALUE! | AD6: =IF(COUNTA(B6:AB6)=0,"",COUNTA(B6:AB6)-COUNTBLANK(B6:AB6)) -> 23 | AF6: https://www.lalucewedding.co.kr/ | AG6: 53.8 | AH6: 58.8 | AI6: 공식 사이트 확인 | AJ6: =IF(OR(C6="강남구",C6="서초구",C6="송파구"),"강남권","비강남권") -> 비강남권 | AK6: =IF(C6="강남구","강남",IF(C6="서초구","서초",IF(C6="송파구","송파",IF(C6="영등포구","영등포",IF(C6="마포구","마포","기타"))))) -> 기타 | AL6: 하우스/야외감성 | AM6: =IF(B6="","",MIN(5,IF(ISNUMBER(SEARCH("역",AC6)),4,IF(AC6<>"",3,2))+IF(Z6<>"",1,0))) -> #VALUE! | AN6: =IF(M6="","",IF(M6<=70000,5,IF(M6<=85000,4,IF(M6<=100000,3,IF(M6<=120000,2,1))))) -> 2 | AO6: =IF(O6="","",IF(O6<=150,5,IF(O6<=200,4,IF(O6<=250,3,IF(O6<=300,2,1))))) -> 4 | AP6: =IF(B6="","",IF(AND(X6="확인",U6>0),5,IF(X6="확인",4,IF(AE6<>"",2,1)))) -> 5 | AQ6: 5 | AR6: 5 | AS6: =IF(B6="","",ROUND(AN6*Assumptions!$B$3+AO6*Assumptions!$B$4+AM6*Assumptions!$B$5+AP6*Assumptions!$B$6+AQ6*Assumptions!$B$7+AR6*Assumptions!$B$8,2)) -> #VALUE! | AT6: =IF(AS6="","",IF(AS6>=4.2,"A",IF(AS6>=3.4,"B","C"))) -> #VALUE! | AU6: =IF(AD6="","",IF(AD6<=25000000,"~2.5억",IF(AD6<=35000000,"2.5~3.5억",IF(AD6<=50000000,"3.5~5억","5억+")))) -> ~2.5억
A7: 10 | B7: 루이비스컨벤션 | C7: 중구 | D7: 서울 중구 청파로 463 | E7: 서울특별시 | F7: 컨벤션 | G7: 어두운홀 | H7: 분리 | I7: 70 | J7: 1 | K7: 뷔페 | L7: 87000 | M7: 87000 | N7: 87000 | O7: 300 | P7: 800 | Q7: 9500000 | R7: - | S7: - | T7: - | U7: - | V7: =IF(AND(T7="",AB7>0),ROUND(AB7*10%,-4),T7) -> - | W7: https://lvconvention.co.kr/main.html | X7: 확인 | Y7: https://map.naver.com/v5/search/루이비스컨벤션 | Z7: 주차가능 | AC7: =IF(AND(L7>0,N7>0),L7*N7+IF(P7="",0,P7)+IF(Q7="",0,Q7)+IF(S7="",0,S7),"") -> #VALUE! | AD7: =IF(COUNTA(B7:AB7)=0,"",COUNTA(B7:AB7)-COUNTBLANK(B7:AB7)) -> 23 | AF7: https://lvconvention.co.kr/main.html | AG7: 55.4 | AH7: 58.8 | AI7: 공식 사이트 확인 | AJ7: =IF(OR(C7="강남구",C7="서초구",C7="송파구"),"강남권","비강남권") -> 비강남권 | AK7: =IF(C7="강남구","강남",IF(C7="서초구","서초",IF(C7="송파구","송파",IF(C7="영등포구","영등포",IF(C7="마포구","마포","기타"))))) -> 기타 | AM7: =IF(B7="","",MIN(5,IF(ISNUMBER(SEARCH("역",AC7)),4,IF(AC7<>"",3,2))+IF(Z7<>"",1,0))) -> #VALUE! | AN7: =IF(M7="","",IF(M7<=70000,5,IF(M7<=85000,4,IF(M7<=100000,3,IF(M7<=120000,2,1))))) -> 3 | AO7: =IF(O7="","",IF(O7<=150,5,IF(O7<=200,4,IF(O7<=250,3,IF(O7<=300,2,1))))) -> 2 | AP7: =IF(B7="","",IF(AND(X7="확인",U7>0),5,IF(X7="확인",4,IF(AE7<>"",2,1)))) -> 5 | AQ7: 3 | AR7: 3 | AS7: =IF(B7="","",ROUND(AN7*Assumptions!$B$3+AO7*Assumptions!$B$4+AM7*Assumptions!$B$5+AP7*Assumptions!$B$6+AQ7*Assumptions!$B$7+AR7*Assumptions!$B$8,2)) -> #VALUE! | AT7: =IF(AS7="","",IF(AS7>=4.2,"A",IF(AS7>=3.4,"B","C"))) -> #VALUE! | AU7: =IF(AD7="","",IF(AD7<=25000000,"~2.5억",IF(AD7<=35000000,"2.5~3.5억",IF(AD7<=50000000,"3.5~5억","5억+")))) -> ~2.5억
A8: 13 | B8: 틸티드 한남 | C8: 용산구 | D8: 서울 용산구 한남대로 150-10 | E8: 서울특별시 | F8: 하우스 | G8: 밝은홀 | H8: 동시 | I8: 360 | J8: 1 | K8: 양식 | L8: 98000 | M8: 98000 | N8: 98000 | O8: 120 | P8: 300 | Q8: 5500000 | R8: - | S8: 9800000 | T8: - | U8: - | V8: =IF(AND(T8="",AB8>0),ROUND(AB8*10%,-4),T8) -> - | X8: 미확인 | Y8: https://map.naver.com/v5/search/틸티드%20한남 | AC8: =IF(AND(L8>0,N8>0),L8*N8+IF(P8="",0,P8)+IF(Q8="",0,Q8)+IF(S8="",0,S8),"") -> 9619300300 | AD8: =IF(COUNTA(B8:AB8)=0,"",COUNTA(B8:AB8)-COUNTBLANK(B8:AB8)) -> 19 | AG8: 52.4 | AH8: 54.8 | AI8: 소규모 후보 | AJ8: =IF(OR(C8="강남구",C8="서초구",C8="송파구"),"강남권","비강남권") -> 비강남권 | AK8: =IF(C8="강남구","강남",IF(C8="서초구","서초",IF(C8="송파구","송파",IF(C8="영등포구","영등포",IF(C8="마포구","마포","기타"))))) -> 기타 | AM8: =IF(B8="","",MIN(5,IF(ISNUMBER(SEARCH("역",AC8)),4,IF(AC8<>"",3,2))+IF(Z8<>"",1,0))) -> 3 | AN8: =IF(M8="","",IF(M8<=70000,5,IF(M8<=85000,4,IF(M8<=100000,3,IF(M8<=120000,2,1))))) -> 3 | AO8: =IF(O8="","",IF(O8<=150,5,IF(O8<=200,4,IF(O8<=250,3,IF(O8<=300,2,1))))) -> 5 | AP8: =IF(B8="","",IF(AND(X8="확인",U8>0),5,IF(X8="확인",4,IF(AE8<>"",2,1)))) -> 1 | AQ8: 3 | AR8: 3 | AS8: =IF(B8="","",ROUND(AN8*Assumptions!$B$3+AO8*Assumptions!$B$4+AM8*Assumptions!$B$5+AP8*Assumptions!$B$6+AQ8*Assumptions!$B$7+AR8*Assumptions!$B$8,2)) -> 2.8 | AT8: =IF(AS8="","",IF(AS8>=4.2,"A",IF(AS8>=3.4,"B","C"))) -> C | AU8: =IF(AD8="","",IF(AD8<=25000000,"~2.5억",IF(AD8<=35000000,"2.5~3.5억",IF(AD8<=50000000,"3.5~5억","5억+")))) -> ~2.5억
A9: 18 | B9: 디노체컨벤션웨딩홀 | C9: 성동구 | D9: 서울 성동구 왕십리광장로 17 | E9: 서울특별시 | F9: 컨벤션 | G9: 어두운홀 | H9: 분리 | I9: 90 | J9: 1 | K9: 뷔페 | L9: 80000 | M9: 80000 | N9: 80000 | O9: 200 | P9: 1000 | Q9: 8000000 | R9: - | S9: - | T9: - | U9: - | V9: =IF(AND(T9="",AB9>0),ROUND(AB9*10%,-4),T9) -> - | X9: 미확인 | Y9: https://map.naver.com/v5/search/디노체컨벤션웨딩홀 | AC9: =IF(AND(L9>0,N9>0),L9*N9+IF(P9="",0,P9)+IF(Q9="",0,Q9)+IF(S9="",0,S9),"") -> #VALUE! | AD9: =IF(COUNTA(B9:AB9)=0,"",COUNTA(B9:AB9)-COUNTBLANK(B9:AB9)) -> 19 | AG9: 61.2 | AH9: 56.8 | AI9: 주소만 반영 | AJ9: =IF(OR(C9="강남구",C9="서초구",C9="송파구"),"강남권","비강남권") -> 비강남권 | AK9: =IF(C9="강남구","강남",IF(C9="서초구","서초",IF(C9="송파구","송파",IF(C9="영등포구","영등포",IF(C9="마포구","마포","기타"))))) -> 기타 | AM9: =IF(B9="","",MIN(5,IF(ISNUMBER(SEARCH("역",AC9)),4,IF(AC9<>"",3,2))+IF(Z9<>"",1,0))) -> #VALUE! | AN9: =IF(M9="","",IF(M9<=70000,5,IF(M9<=85000,4,IF(M9<=100000,3,IF(M9<=120000,2,1))))) -> 4 | AO9: =IF(O9="","",IF(O9<=150,5,IF(O9<=200,4,IF(O9<=250,3,IF(O9<=300,2,1))))) -> 4 | AP9: =IF(B9="","",IF(AND(X9="확인",U9>0),5,IF(X9="확인",4,IF(AE9<>"",2,1)))) -> 1 | AQ9: 3 | AR9: 3 | AS9: =IF(B9="","",ROUND(AN9*Assumptions!$B$3+AO9*Assumptions!$B$4+AM9*Assumptions!$B$5+AP9*Assumptions!$B$6+AQ9*Assumptions!$B$7+AR9*Assumptions!$B$8,2)) -> #VALUE! | AT9: =IF(AS9="","",IF(AS9>=4.2,"A",IF(AS9>=3.4,"B","C"))) -> #VALUE! | AU9: =IF(AD9="","",IF(AD9<=25000000,"~2.5억",IF(AD9<=35000000,"2.5~3.5억",IF(AD9<=50000000,"3.5~5억","5억+")))) -> ~2.5억
A10: 20 | B10: 스타시티아트홀 | C10: 광진구 | D10: 서울 광진구 아차산로 262 | E10: 서울특별시 | F10: 컨벤션 | G10: 밝은홀 | H10: 분리 | I10: 80 | J10: 1 | K10: 한식 | L10: 85000 | M10: 85000 | N10: 85000 | O10: 250 | P10: 700 | Q10: 9000000 | S10: - | T10: - | V10: =IF(AND(T10="",AB10>0),ROUND(AB10*10%,-4),T10) -> - | W10: https://starcityarthall.com/ | X10: 확인 | Y10: https://map.naver.com/v5/search/스타시티아트홀 | Z10: 주차가능 | AC10: =IF(AND(L10>0,N10>0),L10*N10+IF(P10="",0,P10)+IF(Q10="",0,Q10)+IF(S10="",0,S10),"") -> #VALUE! | AD10: =IF(COUNTA(B10:AB10)=0,"",COUNTA(B10:AB10)-COUNTBLANK(B10:AB10)) -> 19 | AF10: https://starcityarthall.com/ | AG10: 65.8 | AH10: 56.8 | AI10: 공식 사이트 확인 | AJ10: =IF(OR(C10="강남구",C10="서초구",C10="송파구"),"강남권","비강남권") -> 비강남권 | AK10: =IF(C10="강남구","강남",IF(C10="서초구","서초",IF(C10="송파구","송파",IF(C10="영등포구","영등포",IF(C10="마포구","마포","기타"))))) -> 기타 | AL10: 도심/밝음 | AM10: =IF(B10="","",MIN(5,IF(ISNUMBER(SEARCH("역",AC10)),4,IF(AC10<>"",3,2))+IF(Z10<>"",1,0))) -> #VALUE! | AN10: =IF(M10="","",IF(M10<=70000,5,IF(M10<=85000,4,IF(M10<=100000,3,IF(M10<=120000,2,1))))) -> 4 | AO10: =IF(O10="","",IF(O10<=150,5,IF(O10<=200,4,IF(O10<=250,3,IF(O10<=300,2,1))))) -> 3 | AP10: =IF(B10="","",IF(AND(X10="확인",U10>0),5,IF(X10="확인",4,IF(AE10<>"",2,1)))) -> 4 | AQ10: 4 | AR10: 4 | AS10: =IF(B10="","",ROUND(AN10*Assumptions!$B$3+AO10*Assumptions!$B$4+AM10*Assumptions!$B$5+AP10*Assumptions!$B$6+AQ10*Assumptions!$B$7+AR10*Assumptions!$B$8,2)) -> #VALUE! | AT10: =IF(AS10="","",IF(AS10>=4.2,"A",IF(AS10>=3.4,"B","C"))) -> #VALUE! | AU10: =IF(AD10="","",IF(AD10<=25000000,"~2.5억",IF(AD10<=35000000,"2.5~3.5억",IF(AD10<=50000000,"3.5~5억","5억+")))) -> ~2.5억
A11: 21 | B11: 벨라루체웨딩홀 서울점 | C11: 동대문구 | D11: 서울 동대문구 망우로 61 | E11: 서울특별시 | F11: 컨벤션 | G11: 혼합 | H11: 분리 | I11: 90 | J11: 3 | K11: 뷔페 | L11: 88000 | M11: 88000 | N11: 88000 | O11: 200 | P11: 350 | Q11: 8800000 | R11: - | S11: - | T11: - | U11: - | V11: =IF(AND(T11="",AB11>0),ROUND(AB11*10%,-4),T11) -> - | W11: https://www.bellaluceseoul.co.kr/ | X11: 확인 | Y11: https://map.naver.com/v5/search/벨라루체웨딩홀%20서울점 | Z11: 주차가능 | AC11: =IF(AND(L11>0,N11>0),L11*N11+IF(P11="",0,P11)+IF(Q11="",0,Q11)+IF(S11="",0,S11),"") -> #VALUE! | AD11: =IF(COUNTA(B11:AB11)=0,"",COUNTA(B11:AB11)-COUNTBLANK(B11:AB11)) -> 23 | AF11: https://www.bellaluceseoul.co.kr/ | AG11: 61.8 | AH11: 60.8 | AI11: 공식 사이트 확인 | AJ11: =IF(OR(C11="강남구",C11="서초구",C11="송파구"),"강남권","비강남권") -> 비강남권 | AK11: =IF(C11="강남구","강남",IF(C11="서초구","서초",IF(C11="송파구","송파",IF(C11="영등포구","영등포",IF(C11="마포구","마포","기타"))))) -> 기타 | AM11: =IF(B11="","",MIN(5,IF(ISNUMBER(SEARCH("역",AC11)),4,IF(AC11<>"",3,2))+IF(Z11<>"",1,0))) -> #VALUE! | AN11: =IF(M11="","",IF(M11<=70000,5,IF(M11<=85000,4,IF(M11<=100000,3,IF(M11<=120000,2,1))))) -> 3 | AO11: =IF(O11="","",IF(O11<=150,5,IF(O11<=200,4,IF(O11<=250,3,IF(O11<=300,2,1))))) -> 4 | AP11: =IF(B11="","",IF(AND(X11="확인",U11>0),5,IF(X11="확인",4,IF(AE11<>"",2,1)))) -> 5 | AQ11: 3 | AR11: 3 | AS11: =IF(B11="","",ROUND(AN11*Assumptions!$B$3+AO11*Assumptions!$B$4+AM11*Assumptions!$B$5+AP11*Assumptions!$B$6+AQ11*Assumptions!$B$7+AR11*Assumptions!$B$8,2)) -> #VALUE! | AT11: =IF(AS11="","",IF(AS11>=4.2,"A",IF(AS11>=3.4,"B","C"))) -> #VALUE! | AU11: =IF(AD11="","",IF(AD11<=25000000,"~2.5억",IF(AD11<=35000000,"2.5~3.5억",IF(AD11<=50000000,"3.5~5억","5억+")))) -> ~2.5억
A12: 23 | B12: DMC타워웨딩 | C12: 마포구 | D12: 서울 마포구 성암로 189 | E12: 서울특별시 | F12: 컨벤션 | G12: 밝은홀 | H12: 분리 | I12: 90 | J12: 3 | K12: 뷔페 | L12: 93000 | M12: 93000 | N12: 93000 | O12: 250 | P12: 500 | Q12: 17000000 | R12: - | S12: - | T12: - | U12: - | V12: =IF(AND(T12="",AB12>0),ROUND(AB12*10%,-4),T12) -> - | W12: https://www.dmcwedding.co.kr/ | X12: 확인 | Y12: https://map.naver.com/v5/search/DMC타워웨딩 | Z12: 주차가능 | AC12: =IF(AND(L12>0,N12>0),L12*N12+IF(P12="",0,P12)+IF(Q12="",0,Q12)+IF(S12="",0,S12),"") -> #VALUE! | AD12: =IF(COUNTA(B12:AB12)=0,"",COUNTA(B12:AB12)-COUNTBLANK(B12:AB12)) -> 23 | AF12: https://www.dmcwedding.co.kr/ | AG12: 44.6 | AH12: 56.8 | AI12: 공식 사이트 확인 | AJ12: =IF(OR(C12="강남구",C12="서초구",C12="송파구"),"강남권","비강남권") -> 비강남권 | AK12: =IF(C12="강남구","강남",IF(C12="서초구","서초",IF(C12="송파구","송파",IF(C12="영등포구","영등포",IF(C12="마포구","마포","기타"))))) -> 마포 | AM12: =IF(B12="","",MIN(5,IF(ISNUMBER(SEARCH("역",AC12)),4,IF(AC12<>"",3,2))+IF(Z12<>"",1,0))) -> #VALUE! | AN12: =IF(M12="","",IF(M12<=70000,5,IF(M12<=85000,4,IF(M12<=100000,3,IF(M12<=120000,2,1))))) -> 3 | AO12: =IF(O12="","",IF(O12<=150,5,IF(O12<=200,4,IF(O12<=250,3,IF(O12<=300,2,1))))) -> 3 | AP12: =IF(B12="","",IF(AND(X12="확인",U12>0),5,IF(X12="확인",4,IF(AE12<>"",2,1)))) -> 5 | AQ12: 3 | AR12: 3 | AS12: =IF(B12="","",ROUND(AN12*Assumptions!$B$3+AO12*Assumptions!$B$4+AM12*Assumptions!$B$5+AP12*Assumptions!$B$6+AQ12*Assumptions!$B$7+AR12*Assumptions!$B$8,2)) -> #VALUE! | AT12: =IF(AS12="","",IF(AS12>=4.2,"A",IF(AS12>=3.4,"B","C"))) -> #VALUE! | AU12: =IF(AD12="","",IF(AD12<=25000000,"~2.5억",IF(AD12<=35000000,"2.5~3.5억",IF(AD12<=50000000,"3.5~5억","5억+")))) -> ~2.5억
A13: 24 | B13: 월드컵컨벤션 | C13: 마포구 | D13: 서울 마포구 월드컵로 240 | E13: 서울특별시 | F13: 컨벤션 | G13: 밝은홀 | H13: 분리 | I13: 90 | J13: 2 | K13: 뷔페 | L13: 89000 | M13: 89000 | N13: 89000 | O13: 250 | P13: 1200 | Q13: 8500000 | R13: - | S13: - | T13: - | U13: - | V13: =IF(AND(T13="",AB13>0),ROUND(AB13*10%,-4),T13) -> - | X13: 미확인 | Y13: https://map.naver.com/v5/search/월드컵컨벤션 | AC13: =IF(AND(L13>0,N13>0),L13*N13+IF(P13="",0,P13)+IF(Q13="",0,Q13)+IF(S13="",0,S13),"") -> #VALUE! | AD13: =IF(COUNTA(B13:AB13)=0,"",COUNTA(B13:AB13)-COUNTBLANK(B13:AB13)) -> 19 | AG13: 45.4 | AH13: 56.8 | AI13: 주소만 반영 | AJ13: =IF(OR(C13="강남구",C13="서초구",C13="송파구"),"강남권","비강남권") -> 비강남권 | AK13: =IF(C13="강남구","강남",IF(C13="서초구","서초",IF(C13="송파구","송파",IF(C13="영등포구","영등포",IF(C13="마포구","마포","기타"))))) -> 마포 | AM13: =IF(B13="","",MIN(5,IF(ISNUMBER(SEARCH("역",AC13)),4,IF(AC13<>"",3,2))+IF(Z13<>"",1,0))) -> #VALUE! | AN13: =IF(M13="","",IF(M13<=70000,5,IF(M13<=85000,4,IF(M13<=100000,3,IF(M13<=120000,2,1))))) -> 3 | AO13: =IF(O13="","",IF(O13<=150,5,IF(O13<=200,4,IF(O13<=250,3,IF(O13<=300,2,1))))) -> 3 | AP13: =IF(B13="","",IF(AND(X13="확인",U13>0),5,IF(X13="확인",4,IF(AE13<>"",2,1)))) -> 1 | AQ13: 3 | AR13: 3 | AS13: =IF(B13="","",ROUND(AN13*Assumptions!$B$3+AO13*Assumptions!$B$4+AM13*Assumptions!$B$5+AP13*Assumptions!$B$6+AQ13*Assumptions!$B$7+AR13*Assumptions!$B$8,2)) -> #VALUE! | AT13: =IF(AS13="","",IF(AS13>=4.2,"A",IF(AS13>=3.4,"B","C"))) -> #VALUE! | AU13: =IF(AD13="","",IF(AD13<=25000000,"~2.5억",IF(AD13<=35000000,"2.5~3.5억",IF(AD13<=50000000,"3.5~5억","5억+")))) -> ~2.5억
A14: 25 | B14: 더파티움 여의도 | C14: 영등포구 | D14: 서울 영등포구 은행로 30 | E14: 서울특별시 | F14: 컨벤션 | G14: 어두운홀 | H14: 분리 | I14: 80 | J14: 2 | K14: 한식 | L14: 121000 | M14: 121000 | N14: 121000 | O14: 300 | P14: 700 | Q14: 16500000 | R14: - | S14: - | T14: - | U14: - | V14: =IF(AND(T14="",AB14>0),ROUND(AB14*10%,-4),T14) -> - | X14: 미확인 | Y14: https://map.naver.com/v5/search/더파티움%20여의도 | AC14: =IF(AND(L14>0,N14>0),L14*N14+IF(P14="",0,P14)+IF(Q14="",0,Q14)+IF(S14="",0,S14),"") -> #VALUE! | AD14: =IF(COUNTA(B14:AB14)=0,"",COUNTA(B14:AB14)-COUNTBLANK(B14:AB14)) -> 19 | AG14: 40.8 | AH14: 46.8 | AI14: 주소만 반영 | AJ14: =IF(OR(C14="강남구",C14="서초구",C14="송파구"),"강남권","비강남권") -> 비강남권 | AK14: =IF(C14="강남구","강남",IF(C14="서초구","서초",IF(C14="송파구","송파",IF(C14="영등포구","영등포",IF(C14="마포구","마포","기타"))))) -> 영등포 | AM14: =IF(B14="","",MIN(5,IF(ISNUMBER(SEARCH("역",AC14)),4,IF(AC14<>"",3,2))+IF(Z14<>"",1,0))) -> #VALUE! | AN14: =IF(M14="","",IF(M14<=70000,5,IF(M14<=85000,4,IF(M14<=100000,3,IF(M14<=120000,2,1))))) -> 1 | AO14: =IF(O14="","",IF(O14<=150,5,IF(O14<=200,4,IF(O14<=250,3,IF(O14<=300,2,1))))) -> 2 | AP14: =IF(B14="","",IF(AND(X14="확인",U14>0),5,IF(X14="확인",4,IF(AE14<>"",2,1)))) -> 1 | AQ14: 3 | AR14: 3 | AS14: =IF(B14="","",ROUND(AN14*Assumptions!$B$3+AO14*Assumptions!$B$4+AM14*Assumptions!$B$5+AP14*Assumptions!$B$6+AQ14*Assumptions!$B$7+AR14*Assumptions!$B$8,2)) -> #VALUE! | AT14: =IF(AS14="","",IF(AS14>=4.2,"A",IF(AS14>=3.4,"B","C"))) -> #VALUE! | AU14: =IF(AD14="","",IF(AD14<=25000000,"~2.5억",IF(AD14<=35000000,"2.5~3.5억",IF(AD14<=50000000,"3.5~5억","5억+")))) -> ~2.5억
A15: 26 | B15: JK아트컨벤션 | C15: 영등포구 | D15: 서울 영등포구 문래로 164 | E15: 서울특별시 | F15: 컨벤션 | G15: 어두운홀 | H15: 분리 | I15: 120 | J15: 3 | K15: 뷔페 | L15: 86000 | M15: 86000 | N15: 86000 | O15: 250 | P15: 800 | Q15: 11000000 | R15: - | S15: - | T15: - | U15: - | V15: =IF(AND(T15="",AB15>0),ROUND(AB15*10%,-4),T15) -> - | W15: https://www.jkart.co.kr/ | X15: 확인 | Y15: https://map.naver.com/v5/search/JK아트컨벤션 | Z15: 주차가능 | AC15: =IF(AND(L15>0,N15>0),L15*N15+IF(P15="",0,P15)+IF(Q15="",0,Q15)+IF(S15="",0,S15),"") -> #VALUE! | AD15: =IF(COUNTA(B15:AB15)=0,"",COUNTA(B15:AB15)-COUNTBLANK(B15:AB15)) -> 23 | AF15: https://www.jkart.co.kr/ | AG15: 41.6 | AH15: 46.8 | AI15: 공식 사이트 확인 | AJ15: =IF(OR(C15="강남구",C15="서초구",C15="송파구"),"강남권","비강남권") -> 비강남권 | AK15: =IF(C15="강남구","강남",IF(C15="서초구","서초",IF(C15="송파구","송파",IF(C15="영등포구","영등포",IF(C15="마포구","마포","기타"))))) -> 영등포 | AM15: =IF(B15="","",MIN(5,IF(ISNUMBER(SEARCH("역",AC15)),4,IF(AC15<>"",3,2))+IF(Z15<>"",1,0))) -> #VALUE! | AN15: =IF(M15="","",IF(M15<=70000,5,IF(M15<=85000,4,IF(M15<=100000,3,IF(M15<=120000,2,1))))) -> 3 | AO15: =IF(O15="","",IF(O15<=150,5,IF(O15<=200,4,IF(O15<=250,3,IF(O15<=300,2,1))))) -> 3 | AP15: =IF(B15="","",IF(AND(X15="확인",U15>0),5,IF(X15="확인",4,IF(AE15<>"",2,1)))) -> 5 | AQ15: 3 | AR15: 3 | AS15: =IF(B15="","",ROUND(AN15*Assumptions!$B$3+AO15*Assumptions!$B$4+AM15*Assumptions!$B$5+AP15*Assumptions!$B$6+AQ15*Assumptions!$B$7+AR15*Assumptions!$B$8,2)) -> #VALUE! | AT15: =IF(AS15="","",IF(AS15>=4.2,"A",IF(AS15>=3.4,"B","C"))) -> #VALUE! | AU15: =IF(AD15="","",IF(AD15<=25000000,"~2.5억",IF(AD15<=35000000,"2.5~3.5억",IF(AD15<=50000000,"3.5~5억","5억+")))) -> ~2.5억
A16: 27 | B16: 그랜드컨벤션센터 | C16: 영등포구 | D16: 서울 영등포구 양평로 58 | E16: 서울특별시 | F16: 컨벤션 | G16: 혼합 | H16: 분리 | I16: 90 | J16: 2 | K16: 뷔페 | L16: 90000 | M16: 90000 | N16: 90000 | O16: 250 | P16: 1200 | Q16: 9500000 | R16: - | S16: - | T16: - | U16: - | V16: =IF(AND(T16="",AB16>0),ROUND(AB16*10%,-4),T16) -> - | W16: https://www.grandconvention.co.kr/ | X16: 확인 | Y16: https://map.naver.com/v5/search/그랜드컨벤션센터 | Z16: 주차가능 | AC16: =IF(AND(L16>0,N16>0),L16*N16+IF(P16="",0,P16)+IF(Q16="",0,Q16)+IF(S16="",0,S16),"") -> #VALUE! | AD16: =IF(COUNTA(B16:AB16)=0,"",COUNTA(B16:AB16)-COUNTBLANK(B16:AB16)) -> 23 | AF16: https://www.grandconvention.co.kr/ | AG16: 42.4 | AH16: 46.8 | AI16: 공식 사이트 + 가격 참고 | AJ16: =IF(OR(C16="강남구",C16="서초구",C16="송파구"),"강남권","비강남권") -> 비강남권 | AK16: =IF(C16="강남구","강남",IF(C16="서초구","서초",IF(C16="송파구","송파",IF(C16="영등포구","영등포",IF(C16="마포구","마포","기타"))))) -> 영등포 | AM16: =IF(B16="","",MIN(5,IF(ISNUMBER(SEARCH("역",AC16)),4,IF(AC16<>"",3,2))+IF(Z16<>"",1,0))) -> #VALUE! | AN16: =IF(M16="","",IF(M16<=70000,5,IF(M16<=85000,4,IF(M16<=100000,3,IF(M16<=120000,2,1))))) -> 3 | AO16: =IF(O16="","",IF(O16<=150,5,IF(O16<=200,4,IF(O16<=250,3,IF(O16<=300,2,1))))) -> 3 | AP16: =IF(B16="","",IF(AND(X16="확인",U16>0),5,IF(X16="확인",4,IF(AE16<>"",2,1)))) -> 5 | AQ16: 3 | AR16: 3 | AS16: =IF(B16="","",ROUND(AN16*Assumptions!$B$3+AO16*Assumptions!$B$4+AM16*Assumptions!$B$5+AP16*Assumptions!$B$6+AQ16*Assumptions!$B$7+AR16*Assumptions!$B$8,2)) -> #VALUE! | AT16: =IF(AS16="","",IF(AS16>=4.2,"A",IF(AS16>=3.4,"B","C"))) -> #VALUE! | AU16: =IF(AD16="","",IF(AD16<=25000000,"~2.5억",IF(AD16<=35000000,"2.5~3.5억",IF(AD16<=50000000,"3.5~5억","5억+")))) -> ~2.5억
A17: 28 | B17: 더컨벤션 영등포 | C17: 영등포구 | D17: 서울 영등포구 국회대로38길 2 | E17: 서울특별시 | F17: 컨벤션 | G17: 어두운홀 | H17: 분리 | I17: 80 | J17: 2 | K17: 뷔페 | L17: 110000 | M17: 110000 | N17: 110000 | O17: 300 | P17: 550 | Q17: 11000000 | R17: - | S17: - | T17: - | U17: - | V17: =IF(AND(T17="",AB17>0),ROUND(AB17*10%,-4),T17) -> - | W17: http://theconvention.co.kr/ydp | X17: 확인 | Y17: https://map.naver.com/v5/search/더컨벤션%20영등포 | Z17: 주차가능 | AC17: =IF(AND(L17>0,N17>0),L17*N17+IF(P17="",0,P17)+IF(Q17="",0,Q17)+IF(S17="",0,S17),"") -> #VALUE! | AD17: =IF(COUNTA(B17:AB17)=0,"",COUNTA(B17:AB17)-COUNTBLANK(B17:AB17)) -> 23 | AF17: http://theconvention.co.kr/ydp | AG17: 43.2 | AH17: 46.8 | AI17: 홀사용료/보증인원 확인 | AJ17: =IF(OR(C17="강남구",C17="서초구",C17="송파구"),"강남권","비강남권") -> 비강남권 | AK17: =IF(C17="강남구","강남",IF(C17="서초구","서초",IF(C17="송파구","송파",IF(C17="영등포구","영등포",IF(C17="마포구","마포","기타"))))) -> 영등포 | AL17: 컨벤션/버진로드 | AM17: =IF(B17="","",MIN(5,IF(ISNUMBER(SEARCH("역",AC17)),4,IF(AC17<>"",3,2))+IF(Z17<>"",1,0))) -> #VALUE! | AN17: =IF(M17="","",IF(M17<=70000,5,IF(M17<=85000,4,IF(M17<=100000,3,IF(M17<=120000,2,1))))) -> 2 | AO17: =IF(O17="","",IF(O17<=150,5,IF(O17<=200,4,IF(O17<=250,3,IF(O17<=300,2,1))))) -> 2 | AP17: =IF(B17="","",IF(AND(X17="확인",U17>0),5,IF(X17="확인",4,IF(AE17<>"",2,1)))) -> 5 | AQ17: 3 | AR17: 4 | AS17: =IF(B17="","",ROUND(AN17*Assumptions!$B$3+AO17*Assumptions!$B$4+AM17*Assumptions!$B$5+AP17*Assumptions!$B$6+AQ17*Assumptions!$B$7+AR17*Assumptions!$B$8,2)) -> #VALUE! | AT17: =IF(AS17="","",IF(AS17>=4.2,"A",IF(AS17>=3.4,"B","C"))) -> #VALUE! | AU17: =IF(AD17="","",IF(AD17<=25000000,"~2.5억",IF(AD17<=35000000,"2.5~3.5억",IF(AD17<=50000000,"3.5~5억","5억+")))) -> ~2.5억
A18: 29 | B18: 웨딩시티 신도림 | C18: 구로구 | D18: 서울 구로구 새말로 97 | E18: 서울특별시 | F18: 컨벤션 | G18: 어두운홀 | H18: 분리 | I18: 80 | J18: 3 | K18: 뷔페 | L18: 60000 | M18: 70000 | N18: 60000~80000 | O18: 300 | P18: 2200 | Q18: 8000000 | S18: 300000 | T18: - | V18: =IF(AND(T18="",AB18>0),ROUND(AB18*10%,-4),T18) -> - | W18: https://www.tmwedding.co.kr/ | X18: 확인 | Y18: https://map.naver.com/v5/search/웨딩시티%20신도림 | Z18: 주차가능 | AC18: =IF(AND(L18>0,N18>0),L18*N18+IF(P18="",0,P18)+IF(Q18="",0,Q18)+IF(S18="",0,S18),"") -> #VALUE! | AD18: =IF(COUNTA(B18:AB18)=0,"",COUNTA(B18:AB18)-COUNTBLANK(B18:AB18)) -> 19 | AF18: https://www.tmwedding.co.kr/ | AG18: 34.8 | AH18: 43.8 | AI18: 공식 사이트 + 가격 참고 | AJ18: =IF(OR(C18="강남구",C18="서초구",C18="송파구"),"강남권","비강남권") -> 비강남권 | AK18: =IF(C18="강남구","강남",IF(C18="서초구","서초",IF(C18="송파구","송파",IF(C18="영등포구","영등포",IF(C18="마포구","마포","기타"))))) -> 기타 | AL18: 가성비/도심 | AM18: =IF(B18="","",MIN(5,IF(ISNUMBER(SEARCH("역",AC18)),4,IF(AC18<>"",3,2))+IF(Z18<>"",1,0))) -> #VALUE! | AN18: =IF(M18="","",IF(M18<=70000,5,IF(M18<=85000,4,IF(M18<=100000,3,IF(M18<=120000,2,1))))) -> 5 | AO18: =IF(O18="","",IF(O18<=150,5,IF(O18<=200,4,IF(O18<=250,3,IF(O18<=300,2,1))))) -> 2 | AP18: =IF(B18="","",IF(AND(X18="확인",U18>0),5,IF(X18="확인",4,IF(AE18<>"",2,1)))) -> 4 | AQ18: 3 | AR18: 4 | AS18: =IF(B18="","",ROUND(AN18*Assumptions!$B$3+AO18*Assumptions!$B$4+AM18*Assumptions!$B$5+AP18*Assumptions!$B$6+AQ18*Assumptions!$B$7+AR18*Assumptions!$B$8,2)) -> #VALUE! | AT18: =IF(AS18="","",IF(AS18>=4.2,"A",IF(AS18>=3.4,"B","C"))) -> #VALUE! | AU18: =IF(AD18="","",IF(AD18<=25000000,"~2.5억",IF(AD18<=35000000,"2.5~3.5억",IF(AD18<=50000000,"3.5~5억","5억+")))) -> ~2.5억
A19: 30 | B19: 더세인트 | C19: 구로구 | D19: 서울 구로구 경인로 662 | E19: 서울특별시 | F19: 컨벤션 | G19: 혼합 | H19: 분리 | I19: 120 | J19: 2 | K19: 한식/양식 | L19: 110000 | M19: 120000 | N19: 110000~130000 | O19: 200 | P19: 350 | Q19: 26000000 | S19: - | T19: - | V19: =IF(AND(T19="",AB19>0),ROUND(AB19*10%,-4),T19) -> - | W19: https://thesaint.co.kr/ | X19: 확인 | Y19: https://map.naver.com/v5/search/더세인트%20신도림 | Z19: 주차가능 | AC19: =IF(AND(L19>0,N19>0),L19*N19+IF(P19="",0,P19)+IF(Q19="",0,Q19)+IF(S19="",0,S19),"") -> #VALUE! | AD19: =IF(COUNTA(B19:AB19)=0,"",COUNTA(B19:AB19)-COUNTBLANK(B19:AB19)) -> 19 | AF19: https://thesaint.co.kr/ | AG19: 35.6 | AH19: 43.8 | AI19: 공식 사이트 확인 | AJ19: =IF(OR(C19="강남구",C19="서초구",C19="송파구"),"강남권","비강남권") -> 비강남권 | AK19: =IF(C19="강남구","강남",IF(C19="서초구","서초",IF(C19="송파구","송파",IF(C19="영등포구","영등포",IF(C19="마포구","마포","기타"))))) -> 기타 | AM19: =IF(B19="","",MIN(5,IF(ISNUMBER(SEARCH("역",AC19)),4,IF(AC19<>"",3,2))+IF(Z19<>"",1,0))) -> #VALUE! | AN19: =IF(M19="","",IF(M19<=70000,5,IF(M19<=85000,4,IF(M19<=100000,3,IF(M19<=120000,2,1))))) -> 2 | AO19: =IF(O19="","",IF(O19<=150,5,IF(O19<=200,4,IF(O19<=250,3,IF(O19<=300,2,1))))) -> 4 | AP19: =IF(B19="","",IF(AND(X19="확인",U19>0),5,IF(X19="확인",4,IF(AE19<>"",2,1)))) -> 4 | AQ19: 3 | AR19: 3 | AS19: =IF(B19="","",ROUND(AN19*Assumptions!$B$3+AO19*Assumptions!$B$4+AM19*Assumptions!$B$5+AP19*Assumptions!$B$6+AQ19*Assumptions!$B$7+AR19*Assumptions!$B$8,2)) -> #VALUE! | AT19: =IF(AS19="","",IF(AS19>=4.2,"A",IF(AS19>=3.4,"B","C"))) -> #VALUE! | AU19: =IF(AD19="","",IF(AD19<=25000000,"~2.5억",IF(AD19<=35000000,"2.5~3.5억",IF(AD19<=50000000,"3.5~5억","5억+")))) -> ~2.5억
A20: 31 | B20: 더뉴컨벤션 | C20: 강서구 | D20: 서울 강서구 화곡로 55 | E20: 서울특별시 | F20: 컨벤션 | G20: 혼합 | H20: 분리 | I20: 80 | J20: 4 | K20: 뷔페 | L20: 82000 | M20: 90000 | N20: 82000~95000 | O20: 200 | P20: 600 | Q20: 13000000 | R20: 9000000 | S20: 3000000 | T20: - | V20: =IF(AND(T20="",AB20>0),ROUND(AB20*10%,-4),T20) -> - | X20: 미확인 | Y20: https://map.naver.com/v5/search/더뉴컨벤션 | AC20: =IF(AND(L20>0,N20>0),L20*N20+IF(P20="",0,P20)+IF(Q20="",0,Q20)+IF(S20="",0,S20),"") -> #VALUE! | AD20: =IF(COUNTA(B20:AB20)=0,"",COUNTA(B20:AB20)-COUNTBLANK(B20:AB20)) -> 17 | AG20: 29.8 | AH20: 50.8 | AI20: 주소 추정/확인필요 | AJ20: =IF(OR(C20="강남구",C20="서초구",C20="송파구"),"강남권","비강남권") -> 비강남권 | AK20: =IF(C20="강남구","강남",IF(C20="서초구","서초",IF(C20="송파구","송파",IF(C20="영등포구","영등포",IF(C20="마포구","마포","기타"))))) -> 기타 | AM20: =IF(B20="","",MIN(5,IF(ISNUMBER(SEARCH("역",AC20)),4,IF(AC20<>"",3,2))+IF(Z20<>"",1,0))) -> #VALUE! | AN20: =IF(M20="","",IF(M20<=70000,5,IF(M20<=85000,4,IF(M20<=100000,3,IF(M20<=120000,2,1))))) -> 3 | AO20: =IF(O20="","",IF(O20<=150,5,IF(O20<=200,4,IF(O20<=250,3,IF(O20<=300,2,1))))) -> 4 | AP20: =IF(B20="","",IF(AND(X20="확인",U20>0),5,IF(X20="확인",4,IF(AE20<>"",2,1)))) -> 1 | AQ20: 3 | AR20: 3 | AS20: =IF(B20="","",ROUND(AN20*Assumptions!$B$3+AO20*Assumptions!$B$4+AM20*Assumptions!$B$5+AP20*Assumptions!$B$6+AQ20*Assumptions!$B$7+AR20*Assumptions!$B$8,2)) -> #VALUE! | AT20: =IF(AS20="","",IF(AS20>=4.2,"A",IF(AS20>=3.4,"B","C"))) -> #VALUE! | AU20: =IF(AD20="","",IF(AD20<=25000000,"~2.5억",IF(AD20<=35000000,"2.5~3.5억",IF(AD20<=50000000,"3.5~5억","5억+")))) -> ~2.5억
A21: 32 | B21: 엘타워 | C21: 서초구 | D21: 서울 서초구 강남대로 213 | E21: 서울특별시 | F21: 컨벤션 | G21: 혼합 | H21: 동시 | I21: 180 | J21: 3 | K21: 한식/양식 | L21: 130000 | M21: 150000 | N21: 130000~170000 | O21: 250 | P21: 800 | Q21: 21000000 | R21: 20000000 | S21: - | T21: - | V21: =IF(AND(T21="",AB21>0),ROUND(AB21*10%,-4),T21) -> - | W21: https://eltower.co.kr/ | X21: 확인 | Y21: https://map.naver.com/v5/search/엘타워 | Z21: 주차가능 | AC21: =IF(AND(L21>0,N21>0),L21*N21+IF(P21="",0,P21)+IF(Q21="",0,Q21)+IF(S21="",0,S21),"") -> #VALUE! | AD21: =IF(COUNTA(B21:AB21)=0,"",COUNTA(B21:AB21)-COUNTBLANK(B21:AB21)) -> 21 | AF21: https://eltower.co.kr/ | AG21: 54.8 | AH21: 42.8 | AI21: 공식 도메인 + 가격 참고 | AJ21: =IF(OR(C21="강남구",C21="서초구",C21="송파구"),"강남권","비강남권") -> 강남권 | AK21: =IF(C21="강남구","강남",IF(C21="서초구","서초",IF(C21="송파구","송파",IF(C21="영등포구","영등포",IF(C21="마포구","마포","기타"))))) -> 서초 | AM21: =IF(B21="","",MIN(5,IF(ISNUMBER(SEARCH("역",AC21)),4,IF(AC21<>"",3,2))+IF(Z21<>"",1,0))) -> #VALUE! | AN21: =IF(M21="","",IF(M21<=70000,5,IF(M21<=85000,4,IF(M21<=100000,3,IF(M21<=120000,2,1))))) -> 1 | AO21: =IF(O21="","",IF(O21<=150,5,IF(O21<=200,4,IF(O21<=250,3,IF(O21<=300,2,1))))) -> 3 | AP21: =IF(B21="","",IF(AND(X21="확인",U21>0),5,IF(X21="확인",4,IF(AE21<>"",2,1)))) -> 4 | AQ21: 3 | AR21: 3 | AS21: =IF(B21="","",ROUND(AN21*Assumptions!$B$3+AO21*Assumptions!$B$4+AM21*Assumptions!$B$5+AP21*Assumptions!$B$6+AQ21*Assumptions!$B$7+AR21*Assumptions!$B$8,2)) -> #VALUE! | AT21: =IF(AS21="","",IF(AS21>=4.2,"A",IF(AS21>=3.4,"B","C"))) -> #VALUE! | AU21: =IF(AD21="","",IF(AD21<=25000000,"~2.5억",IF(AD21<=35000000,"2.5~3.5억",IF(AD21<=50000000,"3.5~5억","5억+")))) -> ~2.5억
A22: 33 | B22: 더화이트베일 | C22: 서초구 | D22: 서울 서초구 서초중앙로 14 | E22: 서울특별시 | F22: 컨벤션 | G22: 혼합 | H22: 분리 | I22: 90 | J22: 2 | K22: 뷔페 | L22: 80000 | M22: 90000 | N22: 80000~95000 | O22: 250 | P22: 950 | Q22: 9500000 | R22: - | S22: - | V22: =IF(AND(T22="",AB22>0),ROUND(AB22*10%,-4),T22) -> 0 | W22: https://thewhiteveil.co.kr/ | X22: 확인 | Y22: https://map.naver.com/v5/search/더화이트베일 | Z22: 주차가능 | AC22: =IF(AND(L22>0,N22>0),L22*N22+IF(P22="",0,P22)+IF(Q22="",0,Q22)+IF(S22="",0,S22),"") -> #VALUE! | AD22: =IF(COUNTA(B22:AB22)=0,"",COUNTA(B22:AB22)-COUNTBLANK(B22:AB22)) -> 19 | AF22: https://thewhiteveil.co.kr/ | AG22: 55.6 | AH22: 42.8 | AI22: 공식 사이트 확인 | AJ22: =IF(OR(C22="강남구",C22="서초구",C22="송파구"),"강남권","비강남권") -> 강남권 | AK22: =IF(C22="강남구","강남",IF(C22="서초구","서초",IF(C22="송파구","송파",IF(C22="영등포구","영등포",IF(C22="마포구","마포","기타"))))) -> 서초 | AL22: 컨벤션/우아 | AM22: =IF(B22="","",MIN(5,IF(ISNUMBER(SEARCH("역",AC22)),4,IF(AC22<>"",3,2))+IF(Z22<>"",1,0))) -> #VALUE! | AN22: =IF(M22="","",IF(M22<=70000,5,IF(M22<=85000,4,IF(M22<=100000,3,IF(M22<=120000,2,1))))) -> 3 | AO22: =IF(O22="","",IF(O22<=150,5,IF(O22<=200,4,IF(O22<=250,3,IF(O22<=300,2,1))))) -> 3 | AP22: =IF(B22="","",IF(AND(X22="확인",U22>0),5,IF(X22="확인",4,IF(AE22<>"",2,1)))) -> 4 | AQ22: 4 | AR22: 5 | AS22: =IF(B22="","",ROUND(AN22*Assumptions!$B$3+AO22*Assumptions!$B$4+AM22*Assumptions!$B$5+AP22*Assumptions!$B$6+AQ22*Assumptions!$B$7+AR22*Assumptions!$B$8,2)) -> #VALUE! | AT22: =IF(AS22="","",IF(AS22>=4.2,"A",IF(AS22>=3.4,"B","C"))) -> #VALUE! | AU22: =IF(AD22="","",IF(AD22<=25000000,"~2.5억",IF(AD22<=35000000,"2.5~3.5억",IF(AD22<=50000000,"3.5~5억","5억+")))) -> ~2.5억
A23: 34 | B23: 아펠가모 반포 | C23: 서초구 | D23: 서울 서초구 반포대로 235 | E23: 서울특별시 | F23: 채플 | G23: 밝은홀 | H23: 분리 | I23: 90 | J23: 1 | K23: 뷔페 | L23: 110000 | M23: 110000 | N23: 110000 | O23: 300 | P23: 550 | Q23: 11000000 | R23: - | S23: - | V23: =IF(AND(T23="",AB23>0),ROUND(AB23*10%,-4),T23) -> 0 | W23: https://apelgamo.com/home/wedding2 | X23: 확인 | Y23: https://map.naver.com/v5/search/아펠가모%20반포 | Z23: 주차가능 | AC23: =IF(AND(L23>0,N23>0),L23*N23+IF(P23="",0,P23)+IF(Q23="",0,Q23)+IF(S23="",0,S23),"") -> #VALUE! | AD23: =IF(COUNTA(B23:AB23)=0,"",COUNTA(B23:AB23)-COUNTBLANK(B23:AB23)) -> 19 | AF23: https://apelgamo.com/home/wedding2 | AG23: 56.4 | AH23: 42.8 | AI23: 공식 지점 확인 | AJ23: =IF(OR(C23="강남구",C23="서초구",C23="송파구"),"강남권","비강남권") -> 강남권 | AK23: =IF(C23="강남구","강남",IF(C23="서초구","서초",IF(C23="송파구","송파",IF(C23="영등포구","영등포",IF(C23="마포구","마포","기타"))))) -> 서초 | AL23: 채플/고전 | AM23: =IF(B23="","",MIN(5,IF(ISNUMBER(SEARCH("역",AC23)),4,IF(AC23<>"",3,2))+IF(Z23<>"",1,0))) -> #VALUE! | AN23: =IF(M23="","",IF(M23<=70000,5,IF(M23<=85000,4,IF(M23<=100000,3,IF(M23<=120000,2,1))))) -> 2 | AO23: =IF(O23="","",IF(O23<=150,5,IF(O23<=200,4,IF(O23<=250,3,IF(O23<=300,2,1))))) -> 2 | AP23: =IF(B23="","",IF(AND(X23="확인",U23>0),5,IF(X23="확인",4,IF(AE23<>"",2,1)))) -> 4 | AQ23: 4 | AR23: 5 | AS23: =IF(B23="","",ROUND(AN23*Assumptions!$B$3+AO23*Assumptions!$B$4+AM23*Assumptions!$B$5+AP23*Assumptions!$B$6+AQ23*Assumptions!$B$7+AR23*Assumptions!$B$8,2)) -> #VALUE! | AT23: =IF(AS23="","",IF(AS23>=4.2,"A",IF(AS23>=3.4,"B","C"))) -> #VALUE! | AU23: =IF(AD23="","",IF(AD23<=25000000,"~2.5억",IF(AD23<=35000000,"2.5~3.5억",IF(AD23<=50000000,"3.5~5억","5억+")))) -> ~2.5억
A24: 36 | B24: 노블발렌티 대치 | C24: 강남구 | D24: 서울 강남구 영동대로 325 | E24: 서울특별시 | F24: 채플 | G24: 밝은홀 | H24: 분리 | I24: 90 | J24: 1 | K24: 뷔페 | L24: 100000 | M24: 100000 | N24: 100000 | O24: 300 | P24: 550 | Q24: 13000000 | R24: - | S24: - | V24: =IF(AND(T24="",AB24>0),ROUND(AB24*10%,-4),T24) -> 0 | W24: https://noblevalentidaechi.co.kr/ | X24: 확인 | Y24: https://map.naver.com/v5/search/노블발렌티%20대치 | Z24: 주차가능 | AC24: =IF(AND(L24>0,N24>0),L24*N24+IF(P24="",0,P24)+IF(Q24="",0,Q24)+IF(S24="",0,S24),"") -> #VALUE! | AD24: =IF(COUNTA(B24:AB24)=0,"",COUNTA(B24:AB24)-COUNTBLANK(B24:AB24)) -> 19 | AF24: https://noblevalentidaechi.co.kr/ | AG24: 60.8 | AH24: 43.8 | AI24: 공식 사이트 + 일부 가격 노출 | AJ24: =IF(OR(C24="강남구",C24="서초구",C24="송파구"),"강남권","비강남권") -> 강남권 | AK24: =IF(C24="강남구","강남",IF(C24="서초구","서초",IF(C24="송파구","송파",IF(C24="영등포구","영등포",IF(C24="마포구","마포","기타"))))) -> 강남 | AM24: =IF(B24="","",MIN(5,IF(ISNUMBER(SEARCH("역",AC24)),4,IF(AC24<>"",3,2))+IF(Z24<>"",1,0))) -> #VALUE! | AN24: =IF(M24="","",IF(M24<=70000,5,IF(M24<=85000,4,IF(M24<=100000,3,IF(M24<=120000,2,1))))) -> 3 | AO24: =IF(O24="","",IF(O24<=150,5,IF(O24<=200,4,IF(O24<=250,3,IF(O24<=300,2,1))))) -> 2 | AP24: =IF(B24="","",IF(AND(X24="확인",U24>0),5,IF(X24="확인",4,IF(AE24<>"",2,1)))) -> 4 | AQ24: 3 | AR24: 3 | AS24: =IF(B24="","",ROUND(AN24*Assumptions!$B$3+AO24*Assumptions!$B$4+AM24*Assumptions!$B$5+AP24*Assumptions!$B$6+AQ24*Assumptions!$B$7+AR24*Assumptions!$B$8,2)) -> #VALUE! | AT24: =IF(AS24="","",IF(AS24>=4.2,"A",IF(AS24>=3.4,"B","C"))) -> #VALUE! | AU24: =IF(AD24="","",IF(AD24<=25000000,"~2.5억",IF(AD24<=35000000,"2.5~3.5억",IF(AD24<=50000000,"3.5~5억","5억+")))) -> ~2.5억
A25: 37 | B25: 노블발렌티 삼성 | C25: 강남구 | D25: 서울 강남구 봉은사로 637 | E25: 서울특별시 | F25: 채플 | G25: 밝은홀 | H25: 분리 | I25: 120 | J25: 1 | K25: 양식 | L25: 100000 | M25: 100000 | N25: 100000 | O25: 300 | P25: 550 | Q25: 13000000 | R25: - | S25: - | V25: =IF(AND(T25="",AB25>0),ROUND(AB25*10%,-4),T25) -> 0 | W25: https://noblevalenti.co.kr/ | X25: 확인 | Y25: https://map.naver.com/v5/search/노블발렌티%20삼성 | Z25: 주차가능 | AC25: =IF(AND(L25>0,N25>0),L25*N25+IF(P25="",0,P25)+IF(Q25="",0,Q25)+IF(S25="",0,S25),"") -> #VALUE! | AD25: =IF(COUNTA(B25:AB25)=0,"",COUNTA(B25:AB25)-COUNTBLANK(B25:AB25)) -> 19 | AF25: https://noblevalenti.co.kr/ | AG25: 61.6 | AH25: 43.8 | AI25: 공식 사이트 확인 | AJ25: =IF(OR(C25="강남구",C25="서초구",C25="송파구"),"강남권","비강남권") -> 강남권 | AK25: =IF(C25="강남구","강남",IF(C25="서초구","서초",IF(C25="송파구","송파",IF(C25="영등포구","영등포",IF(C25="마포구","마포","기타"))))) -> 강남 | AM25: =IF(B25="","",MIN(5,IF(ISNUMBER(SEARCH("역",AC25)),4,IF(AC25<>"",3,2))+IF(Z25<>"",1,0))) -> #VALUE! | AN25: =IF(M25="","",IF(M25<=70000,5,IF(M25<=85000,4,IF(M25<=100000,3,IF(M25<=120000,2,1))))) -> 3 | AO25: =IF(O25="","",IF(O25<=150,5,IF(O25<=200,4,IF(O25<=250,3,IF(O25<=300,2,1))))) -> 2 | AP25: =IF(B25="","",IF(AND(X25="확인",U25>0),5,IF(X25="확인",4,IF(AE25<>"",2,1)))) -> 4 | AQ25: 3 | AR25: 3 | AS25: =IF(B25="","",ROUND(AN25*Assumptions!$B$3+AO25*Assumptions!$B$4+AM25*Assumptions!$B$5+AP25*Assumptions!$B$6+AQ25*Assumptions!$B$7+AR25*Assumptions!$B$8,2)) -> #VALUE! | AT25: =IF(AS25="","",IF(AS25>=4.2,"A",IF(AS25>=3.4,"B","C"))) -> #VALUE! | AU25: =IF(AD25="","",IF(AD25<=25000000,"~2.5억",IF(AD25<=35000000,"2.5~3.5억",IF(AD25<=50000000,"3.5~5억","5억+")))) -> ~2.5억
A26: 38 | B26: 빌라드지디 청담 | C26: 강남구 | D26: 서울 강남구 학동로 519 | E26: 서울특별시 | F26: 하우스 | G26: 밝은홀 | H26: 동시 | I26: 180 | J26: 1 | K26: 양식 | L26: 130000 | M26: 150000 | N26: 130000~170000 | O26: 270 | P26: 380 | Q26: 17000000 | R26: - | S26: - | T26: 13000000 | V26: =IF(AND(T26="",AB26>0),ROUND(AB26*10%,-4),T26) -> 13000000 | W26: https://chungdamvilladegd.com/ | X26: 확인 | Y26: https://map.naver.com/v5/search/빌라드지디%20청담 | Z26: 주차가능 | AC26: =IF(AND(L26>0,N26>0),L26*N26+IF(P26="",0,P26)+IF(Q26="",0,Q26)+IF(S26="",0,S26),"") -> #VALUE! | AD26: =IF(COUNTA(B26:AB26)=0,"",COUNTA(B26:AB26)-COUNTBLANK(B26:AB26)) -> 21 | AF26: https://chungdamvilladegd.com/ | AG26: 62.4 | AH26: 43.8 | AI26: 공식 사이트 확인 | AJ26: =IF(OR(C26="강남구",C26="서초구",C26="송파구"),"강남권","비강남권") -> 강남권 | AK26: =IF(C26="강남구","강남",IF(C26="서초구","서초",IF(C26="송파구","송파",IF(C26="영등포구","영등포",IF(C26="마포구","마포","기타"))))) -> 강남 | AL26: 하우스/무드 | AM26: =IF(B26="","",MIN(5,IF(ISNUMBER(SEARCH("역",AC26)),4,IF(AC26<>"",3,2))+IF(Z26<>"",1,0))) -> #VALUE! | AN26: =IF(M26="","",IF(M26<=70000,5,IF(M26<=85000,4,IF(M26<=100000,3,IF(M26<=120000,2,1))))) -> 1 | AO26: =IF(O26="","",IF(O26<=150,5,IF(O26<=200,4,IF(O26<=250,3,IF(O26<=300,2,1))))) -> 2 | AP26: =IF(B26="","",IF(AND(X26="확인",U26>0),5,IF(X26="확인",4,IF(AE26<>"",2,1)))) -> 4 | AQ26: 5 | AR26: 4 | AS26: =IF(B26="","",ROUND(AN26*Assumptions!$B$3+AO26*Assumptions!$B$4+AM26*Assumptions!$B$5+AP26*Assumptions!$B$6+AQ26*Assumptions!$B$7+AR26*Assumptions!$B$8,2)) -> #VALUE! | AT26: =IF(AS26="","",IF(AS26>=4.2,"A",IF(AS26>=3.4,"B","C"))) -> #VALUE! | AU26: =IF(AD26="","",IF(AD26<=25000000,"~2.5억",IF(AD26<=35000000,"2.5~3.5억",IF(AD26<=50000000,"3.5~5억","5억+")))) -> ~2.5억
A27: 39 | B27: 빌라드지디 수서 | C27: 강남구 | D27: 서울 강남구 밤고개로21길 79 | E27: 서울특별시 | F27: 하우스 | G27: 밝은홀 | H27: 분리 | I27: 150 | J27: 1 | K27: 뷔페 | L27: 99000 | M27: 99000 | N27: 99000 | O27: 300 | P27: 500 | Q27: 12000000 | S27: - | T27: 8800000 | U27: 3000000 | V27: =IF(AND(T27="",AB27>0),ROUND(AB27*10%,-4),T27) -> 8800000 | W27: https://suseovilladegd.com/ | X27: 확인 | Y27: https://map.naver.com/v5/search/빌라드지디%20수서 | Z27: 주차가능 | AC27: =IF(AND(L27>0,N27>0),L27*N27+IF(P27="",0,P27)+IF(Q27="",0,Q27)+IF(S27="",0,S27),"") -> #VALUE! | AD27: =IF(COUNTA(B27:AB27)=0,"",COUNTA(B27:AB27)-COUNTBLANK(B27:AB27)) -> 21 | AF27: https://suseovilladegd.com/FAQ | AG27: 63.2 | AH27: 43.8 | AI27: FAQ에서 계약금 300만원 확인 | AJ27: =IF(OR(C27="강남구",C27="서초구",C27="송파구"),"강남권","비강남권") -> 강남권 | AK27: =IF(C27="강남구","강남",IF(C27="서초구","서초",IF(C27="송파구","송파",IF(C27="영등포구","영등포",IF(C27="마포구","마포","기타"))))) -> 강남 | AL27: 가든/유리정원 | AM27: =IF(B27="","",MIN(5,IF(ISNUMBER(SEARCH("역",AC27)),4,IF(AC27<>"",3,2))+IF(Z27<>"",1,0))) -> #VALUE! | AN27: =IF(M27="","",IF(M27<=70000,5,IF(M27<=85000,4,IF(M27<=100000,3,IF(M27<=120000,2,1))))) -> 3 | AO27: =IF(O27="","",IF(O27<=150,5,IF(O27<=200,4,IF(O27<=250,3,IF(O27<=300,2,1))))) -> 2 | AP27: =IF(B27="","",IF(AND(X27="확인",U27>0),5,IF(X27="확인",4,IF(AE27<>"",2,1)))) -> 5 | AQ27: 5 | AR27: 4 | AS27: =IF(B27="","",ROUND(AN27*Assumptions!$B$3+AO27*Assumptions!$B$4+AM27*Assumptions!$B$5+AP27*Assumptions!$B$6+AQ27*Assumptions!$B$7+AR27*Assumptions!$B$8,2)) -> #VALUE! | AT27: =IF(AS27="","",IF(AS27>=4.2,"A",IF(AS27>=3.4,"B","C"))) -> #VALUE! | AU27: =IF(AD27="","",IF(AD27<=25000000,"~2.5억",IF(AD27<=35000000,"2.5~3.5억",IF(AD27<=50000000,"3.5~5억","5억+")))) -> ~2.5억
A28: 40 | B28: 더채플앳청담 | C28: 강남구 | D28: 서울 강남구 선릉로 757 | E28: 서울특별시 | F28: 채플 | G28: 밝은홀 | H28: 분리 | I28: 90 | J28: 2 | K28: 뷔페 | L28: 120000 | M28: 120000 | N28: 120000 | O28: 300 | P28: 500 | Q28: 12000000 | R28: - | S28: - | T28: - | V28: =IF(AND(T28="",AB28>0),ROUND(AB28*10%,-4),T28) -> - | W28: https://www.thechapel.co.kr/home/wedding1 | X28: 확인 | Y28: https://map.naver.com/v5/search/더채플앳청담 | Z28: 주차가능 | AC28: =IF(AND(L28>0,N28>0),L28*N28+IF(P28="",0,P28)+IF(Q28="",0,Q28)+IF(S28="",0,S28),"") -> #VALUE! | AD28: =IF(COUNTA(B28:AB28)=0,"",COUNTA(B28:AB28)-COUNTBLANK(B28:AB28)) -> 21 | AF28: https://www.thechapel.co.kr/home/wedding1 | AG28: 60.8 | AH28: 44.6 | AI28: 공식 사이트 확인 | AJ28: =IF(OR(C28="강남구",C28="서초구",C28="송파구"),"강남권","비강남권") -> 강남권 | AK28: =IF(C28="강남구","강남",IF(C28="서초구","서초",IF(C28="송파구","송파",IF(C28="영등포구","영등포",IF(C28="마포구","마포","기타"))))) -> 강남 | AL28: 채플/클래식 | AM28: =IF(B28="","",MIN(5,IF(ISNUMBER(SEARCH("역",AC28)),4,IF(AC28<>"",3,2))+IF(Z28<>"",1,0))) -> #VALUE! | AN28: =IF(M28="","",IF(M28<=70000,5,IF(M28<=85000,4,IF(M28<=100000,3,IF(M28<=120000,2,1))))) -> 2 | AO28: =IF(O28="","",IF(O28<=150,5,IF(O28<=200,4,IF(O28<=250,3,IF(O28<=300,2,1))))) -> 2 | AP28: =IF(B28="","",IF(AND(X28="확인",U28>0),5,IF(X28="확인",4,IF(AE28<>"",2,1)))) -> 4 | AQ28: 5 | AR28: 5 | AS28: =IF(B28="","",ROUND(AN28*Assumptions!$B$3+AO28*Assumptions!$B$4+AM28*Assumptions!$B$5+AP28*Assumptions!$B$6+AQ28*Assumptions!$B$7+AR28*Assumptions!$B$8,2)) -> #VALUE! | AT28: =IF(AS28="","",IF(AS28>=4.2,"A",IF(AS28>=3.4,"B","C"))) -> #VALUE! | AU28: =IF(AD28="","",IF(AD28<=25000000,"~2.5억",IF(AD28<=35000000,"2.5~3.5억",IF(AD28<=50000000,"3.5~5억","5억+")))) -> ~2.5억
A29: 41 | B29: 상록아트홀 | C29: 강남구 | D29: 서울 강남구 언주로 508 상록회관 5층 | E29: 서울특별시 | F29: 컨벤션 | G29: 혼합 | H29: 분리 | I29: 80 | J29: 2 | K29: 뷔페 | L29: 98000 | M29: 98000 | N29: 98000 | O29: 250 | P29: 500 | Q29: 9800000 | R29: - | S29: - | T29: - | V29: =IF(AND(T29="",AB29>0),ROUND(AB29*10%,-4),T29) -> - | W29: https://srwedding.co.kr/ | X29: 확인 | Y29: https://map.naver.com/v5/search/상록아트홀 | Z29: 주차가능 | AC29: =IF(AND(L29>0,N29>0),L29*N29+IF(P29="",0,P29)+IF(Q29="",0,Q29)+IF(S29="",0,S29),"") -> #VALUE! | AD29: =IF(COUNTA(B29:AB29)=0,"",COUNTA(B29:AB29)-COUNTBLANK(B29:AB29)) -> 21 | AF29: https://srwedding.co.kr/ | AG29: 61.6 | AH29: 44.6 | AI29: 공식 사이트 + 가격 참고 | AJ29: =IF(OR(C29="강남구",C29="서초구",C29="송파구"),"강남권","비강남권") -> 강남권 | AK29: =IF(C29="강남구","강남",IF(C29="서초구","서초",IF(C29="송파구","송파",IF(C29="영등포구","영등포",IF(C29="마포구","마포","기타"))))) -> 강남 | AL29: 호텔식/웅장 | AM29: =IF(B29="","",MIN(5,IF(ISNUMBER(SEARCH("역",AC29)),4,IF(AC29<>"",3,2))+IF(Z29<>"",1,0))) -> #VALUE! | AN29: =IF(M29="","",IF(M29<=70000,5,IF(M29<=85000,4,IF(M29<=100000,3,IF(M29<=120000,2,1))))) -> 3 | AO29: =IF(O29="","",IF(O29<=150,5,IF(O29<=200,4,IF(O29<=250,3,IF(O29<=300,2,1))))) -> 3 | AP29: =IF(B29="","",IF(AND(X29="확인",U29>0),5,IF(X29="확인",4,IF(AE29<>"",2,1)))) -> 4 | AQ29: 4 | AR29: 4 | AS29: =IF(B29="","",ROUND(AN29*Assumptions!$B$3+AO29*Assumptions!$B$4+AM29*Assumptions!$B$5+AP29*Assumptions!$B$6+AQ29*Assumptions!$B$7+AR29*Assumptions!$B$8,2)) -> #VALUE! | AT29: =IF(AS29="","",IF(AS29>=4.2,"A",IF(AS29>=3.4,"B","C"))) -> #VALUE! | AU29: =IF(AD29="","",IF(AD29<=25000000,"~2.5억",IF(AD29<=35000000,"2.5~3.5억",IF(AD29<=50000000,"3.5~5억","5억+")))) -> ~2.5억 | AV29: 공무원 할인 식대 -2000
A30: 43 | B30: 라온제나강남 | C30: 강남구 | D30: 서울 강남구 언주로 564 인근 | E30: 서울특별시 | F30: 복합홀 | G30: 혼합 | H30: 분리 | I30: 90 | J30: 2 | K30: 뷔페 | L30: 77000 | M30: 77000 | N30: 77000 | O30: 250 | P30: 600 | Q30: 7700000 | R30: - | S30: - | T30: - | V30: =IF(AND(T30="",AB30>0),ROUND(AB30*10%,-4),T30) -> - | W30: https://xn--939ao9fob394buxtzvc.com/ | X30: 확인 | Y30: https://map.naver.com/v5/search/라온제나강남 | Z30: 주차가능 | AC30: =IF(AND(L30>0,N30>0),L30*N30+IF(P30="",0,P30)+IF(Q30="",0,Q30)+IF(S30="",0,S30),"") -> #VALUE! | AD30: =IF(COUNTA(B30:AB30)=0,"",COUNTA(B30:AB30)-COUNTBLANK(B30:AB30)) -> 21 | AF30: https://xn--939ao9fob394buxtzvc.com/ | AG30: 63.2 | AH30: 44.6 | AI30: 공식 사이트 확인 / 상세주소 재확인 | AJ30: =IF(OR(C30="강남구",C30="서초구",C30="송파구"),"강남권","비강남권") -> 강남권 | AK30: =IF(C30="강남구","강남",IF(C30="서초구","서초",IF(C30="송파구","송파",IF(C30="영등포구","영등포",IF(C30="마포구","마포","기타"))))) -> 강남 | AM30: =IF(B30="","",MIN(5,IF(ISNUMBER(SEARCH("역",AC30)),4,IF(AC30<>"",3,2))+IF(Z30<>"",1,0))) -> #VALUE! | AN30: =IF(M30="","",IF(M30<=70000,5,IF(M30<=85000,4,IF(M30<=100000,3,IF(M30<=120000,2,1))))) -> 4 | AO30: =IF(O30="","",IF(O30<=150,5,IF(O30<=200,4,IF(O30<=250,3,IF(O30<=300,2,1))))) -> 3 | AP30: =IF(B30="","",IF(AND(X30="확인",U30>0),5,IF(X30="확인",4,IF(AE30<>"",2,1)))) -> 4 | AQ30: 3 | AR30: 3 | AS30: =IF(B30="","",ROUND(AN30*Assumptions!$B$3+AO30*Assumptions!$B$4+AM30*Assumptions!$B$5+AP30*Assumptions!$B$6+AQ30*Assumptions!$B$7+AR30*Assumptions!$B$8,2)) -> #VALUE! | AT30: =IF(AS30="","",IF(AS30>=4.2,"A",IF(AS30>=3.4,"B","C"))) -> #VALUE! | AU30: =IF(AD30="","",IF(AD30<=25000000,"~2.5억",IF(AD30<=35000000,"2.5~3.5억",IF(AD30<=50000000,"3.5~5억","5억+")))) -> ~2.5억
A31: 44 | B31: 샐럽앤어셈 | C31: 강남구 | D31: 서울 강남구 선릉로 818 | E31: 서울특별시 | F31: 하우스 | G31: 밝은홀 | H31: 분리 | I31: 90 | J31: 1 | K31: 뷔페 | L31: 98000 | M31: 98000 | N31: 98000 | O31: 330 | P31: 500 | Q31: 14500000 | R31: - | S31: - | T31: - | V31: =IF(AND(T31="",AB31>0),ROUND(AB31*10%,-4),T31) -> - | X31: 미확인 | Y31: https://map.naver.com/v5/search/샐럽앤어셈 | AC31: =IF(AND(L31>0,N31>0),L31*N31+IF(P31="",0,P31)+IF(Q31="",0,Q31)+IF(S31="",0,S31),"") -> #VALUE! | AD31: =IF(COUNTA(B31:AB31)=0,"",COUNTA(B31:AB31)-COUNTBLANK(B31:AB31)) -> 17 | AG31: 60.8 | AH31: 45.4 | AI31: 주소 추정/확인필요 | AJ31: =IF(OR(C31="강남구",C31="서초구",C31="송파구"),"강남권","비강남권") -> 강남권 | AK31: =IF(C31="강남구","강남",IF(C31="서초구","서초",IF(C31="송파구","송파",IF(C31="영등포구","영등포",IF(C31="마포구","마포","기타"))))) -> 강남 | AM31: =IF(B31="","",MIN(5,IF(ISNUMBER(SEARCH("역",AC31)),4,IF(AC31<>"",3,2))+IF(Z31<>"",1,0))) -> #VALUE! | AN31: =IF(M31="","",IF(M31<=70000,5,IF(M31<=85000,4,IF(M31<=100000,3,IF(M31<=120000,2,1))))) -> 3 | AO31: =IF(O31="","",IF(O31<=150,5,IF(O31<=200,4,IF(O31<=250,3,IF(O31<=300,2,1))))) -> 1 | AP31: =IF(B31="","",IF(AND(X31="확인",U31>0),5,IF(X31="확인",4,IF(AE31<>"",2,1)))) -> 1 | AQ31: 3 | AR31: 3 | AS31: =IF(B31="","",ROUND(AN31*Assumptions!$B$3+AO31*Assumptions!$B$4+AM31*Assumptions!$B$5+AP31*Assumptions!$B$6+AQ31*Assumptions!$B$7+AR31*Assumptions!$B$8,2)) -> #VALUE! | AT31: =IF(AS31="","",IF(AS31>=4.2,"A",IF(AS31>=3.4,"B","C"))) -> #VALUE! | AU31: =IF(AD31="","",IF(AD31<=25000000,"~2.5억",IF(AD31<=35000000,"2.5~3.5억",IF(AD31<=50000000,"3.5~5억","5억+")))) -> ~2.5억
A32: 45 | B32: 스카이뷰컨벤션 | C32: 강남구 | D32: 서울 강남구 테헤란로 152 | E32: 서울특별시 | F32: 컨벤션 | G32: 혼합 | H32: 분리 | I32: 90 | J32: 1 | K32: 뷔페 | L32: 63000 | M32: 63000 | N32: 25000~63000 | O32: 250 | P32: 350 | Q32: 6600000 | R32: - | S32: - | T32: - | V32: =IF(AND(T32="",AB32>0),ROUND(AB32*10%,-4),T32) -> - | X32: 미확인 | Y32: https://map.naver.com/v5/search/스카이뷰컨벤션 | AC32: =IF(AND(L32>0,N32>0),L32*N32+IF(P32="",0,P32)+IF(Q32="",0,Q32)+IF(S32="",0,S32),"") -> #VALUE! | AD32: =IF(COUNTA(B32:AB32)=0,"",COUNTA(B32:AB32)-COUNTBLANK(B32:AB32)) -> 17 | AG32: 61.6 | AH32: 45.4 | AI32: 주소 추정/확인필요 | AJ32: =IF(OR(C32="강남구",C32="서초구",C32="송파구"),"강남권","비강남권") -> 강남권 | AK32: =IF(C32="강남구","강남",IF(C32="서초구","서초",IF(C32="송파구","송파",IF(C32="영등포구","영등포",IF(C32="마포구","마포","기타"))))) -> 강남 | AM32: =IF(B32="","",MIN(5,IF(ISNUMBER(SEARCH("역",AC32)),4,IF(AC32<>"",3,2))+IF(Z32<>"",1,0))) -> #VALUE! | AN32: =IF(M32="","",IF(M32<=70000,5,IF(M32<=85000,4,IF(M32<=100000,3,IF(M32<=120000,2,1))))) -> 5 | AO32: =IF(O32="","",IF(O32<=150,5,IF(O32<=200,4,IF(O32<=250,3,IF(O32<=300,2,1))))) -> 3 | AP32: =IF(B32="","",IF(AND(X32="확인",U32>0),5,IF(X32="확인",4,IF(AE32<>"",2,1)))) -> 1 | AQ32: 3 | AR32: 3 | AS32: =IF(B32="","",ROUND(AN32*Assumptions!$B$3+AO32*Assumptions!$B$4+AM32*Assumptions!$B$5+AP32*Assumptions!$B$6+AQ32*Assumptions!$B$7+AR32*Assumptions!$B$8,2)) -> #VALUE! | AT32: =IF(AS32="","",IF(AS32>=4.2,"A",IF(AS32>=3.4,"B","C"))) -> #VALUE! | AU32: =IF(AD32="","",IF(AD32<=25000000,"~2.5억",IF(AD32<=35000000,"2.5~3.5억",IF(AD32<=50000000,"3.5~5억","5억+")))) -> ~2.5억
A33: 46 | B33: 더라빌 | C33: 강남구 | D33: 서울 강남구 봉은사로 531 | E33: 서울특별시 | F33: 컨벤션 | G33: 어두운홀 | H33: 분리 | I33: 180 | J33: 2 | K33: 양식 | L33: 87000 | M33: 111000 | N33: 87000~137000 | O33: 200 | P33: 800 | Q33: 8000000 | S33: 1000000 | T33: 8000000 | V33: =IF(AND(T33="",AB33>0),ROUND(AB33*10%,-4),T33) -> 8000000 | X33: 미확인 | Y33: https://map.naver.com/v5/search/더라빌 | AC33: =IF(AND(L33>0,N33>0),L33*N33+IF(P33="",0,P33)+IF(Q33="",0,Q33)+IF(S33="",0,S33),"") -> #VALUE! | AD33: =IF(COUNTA(B33:AB33)=0,"",COUNTA(B33:AB33)-COUNTBLANK(B33:AB33)) -> 15 | AG33: 62.4 | AH33: 45.4 | AI33: 주소 추정/확인필요 | AJ33: =IF(OR(C33="강남구",C33="서초구",C33="송파구"),"강남권","비강남권") -> 강남권 | AK33: =IF(C33="강남구","강남",IF(C33="서초구","서초",IF(C33="송파구","송파",IF(C33="영등포구","영등포",IF(C33="마포구","마포","기타"))))) -> 강남 | AM33: =IF(B33="","",MIN(5,IF(ISNUMBER(SEARCH("역",AC33)),4,IF(AC33<>"",3,2))+IF(Z33<>"",1,0))) -> #VALUE! | AN33: =IF(M33="","",IF(M33<=70000,5,IF(M33<=85000,4,IF(M33<=100000,3,IF(M33<=120000,2,1))))) -> 2 | AO33: =IF(O33="","",IF(O33<=150,5,IF(O33<=200,4,IF(O33<=250,3,IF(O33<=300,2,1))))) -> 4 | AP33: =IF(B33="","",IF(AND(X33="확인",U33>0),5,IF(X33="확인",4,IF(AE33<>"",2,1)))) -> 1 | AQ33: 3 | AR33: 3 | AS33: =IF(B33="","",ROUND(AN33*Assumptions!$B$3+AO33*Assumptions!$B$4+AM33*Assumptions!$B$5+AP33*Assumptions!$B$6+AQ33*Assumptions!$B$7+AR33*Assumptions!$B$8,2)) -> #VALUE! | AT33: =IF(AS33="","",IF(AS33>=4.2,"A",IF(AS33>=3.4,"B","C"))) -> #VALUE! | AU33: =IF(AD33="","",IF(AD33<=25000000,"~2.5억",IF(AD33<=35000000,"2.5~3.5억",IF(AD33<=50000000,"3.5~5억","5억+")))) -> ~2.5억
A34: 47 | B34: 브라이드밸리 | C34: 강남구 | D34: 서울 강남구 봉은사로 637 | E34: 서울특별시 | F34: 컨벤션 | G34: 밝은홀 | H34: 분리 | I34: 90 | J34: 1 | K34: 뷔페 | L34: 85000 | M34: 85000 | N34: 85000 | O34: 250 | P34: 600 | Q34: 8500000 | R34: - | S34: - | T34: - | V34: =IF(AND(T34="",AB34>0),ROUND(AB34*10%,-4),T34) -> - | X34: 미확인 | Y34: https://map.naver.com/v5/search/브라이드밸리 | AC34: =IF(AND(L34>0,N34>0),L34*N34+IF(P34="",0,P34)+IF(Q34="",0,Q34)+IF(S34="",0,S34),"") -> #VALUE! | AD34: =IF(COUNTA(B34:AB34)=0,"",COUNTA(B34:AB34)-COUNTBLANK(B34:AB34)) -> 17 | AG34: 63.2 | AH34: 45.4 | AI34: 확인필요 | AJ34: =IF(OR(C34="강남구",C34="서초구",C34="송파구"),"강남권","비강남권") -> 강남권 | AK34: =IF(C34="강남구","강남",IF(C34="서초구","서초",IF(C34="송파구","송파",IF(C34="영등포구","영등포",IF(C34="마포구","마포","기타"))))) -> 강남 | AM34: =IF(B34="","",MIN(5,IF(ISNUMBER(SEARCH("역",AC34)),4,IF(AC34<>"",3,2))+IF(Z34<>"",1,0))) -> #VALUE! | AN34: =IF(M34="","",IF(M34<=70000,5,IF(M34<=85000,4,IF(M34<=100000,3,IF(M34<=120000,2,1))))) -> 4 | AO34: =IF(O34="","",IF(O34<=150,5,IF(O34<=200,4,IF(O34<=250,3,IF(O34<=300,2,1))))) -> 3 | AP34: =IF(B34="","",IF(AND(X34="확인",U34>0),5,IF(X34="확인",4,IF(AE34<>"",2,1)))) -> 1 | AQ34: 3 | AR34: 3 | AS34: =IF(B34="","",ROUND(AN34*Assumptions!$B$3+AO34*Assumptions!$B$4+AM34*Assumptions!$B$5+AP34*Assumptions!$B$6+AQ34*Assumptions!$B$7+AR34*Assumptions!$B$8,2)) -> #VALUE! | AT34: =IF(AS34="","",IF(AS34>=4.2,"A",IF(AS34>=3.4,"B","C"))) -> #VALUE! | AU34: =IF(AD34="","",IF(AD34<=25000000,"~2.5억",IF(AD34<=35000000,"2.5~3.5억",IF(AD34<=50000000,"3.5~5억","5억+")))) -> ~2.5억
A35: 48 | B35: 그랜드힐컨벤션 | C35: 강남구 | D35: 서울 강남구 역삼로 607 | E35: 서울특별시 | F35: 컨벤션 | G35: 어두운홀 | H35: 동시 | I35: 180 | J35: 3 | K35: 양식 | L35: 99000 | M35: 119000 | N35: 99000~130000 | O35: 250 | P35: 360 | Q35: 12000000 | R35: 12000000 | S35: - | T35: - | V35: =IF(AND(T35="",AB35>0),ROUND(AB35*10%,-4),T35) -> - | X35: 미확인 | Y35: https://map.naver.com/v5/search/그랜드힐컨벤션 | AC35: =IF(AND(L35>0,N35>0),L35*N35+IF(P35="",0,P35)+IF(Q35="",0,Q35)+IF(S35="",0,S35),"") -> #VALUE! | AD35: =IF(COUNTA(B35:AB35)=0,"",COUNTA(B35:AB35)-COUNTBLANK(B35:AB35)) -> 17 | AG35: 60.8 | AH35: 46.2 | AI35: 확인필요 | AJ35: =IF(OR(C35="강남구",C35="서초구",C35="송파구"),"강남권","비강남권") -> 강남권 | AK35: =IF(C35="강남구","강남",IF(C35="서초구","서초",IF(C35="송파구","송파",IF(C35="영등포구","영등포",IF(C35="마포구","마포","기타"))))) -> 강남 | AM35: =IF(B35="","",MIN(5,IF(ISNUMBER(SEARCH("역",AC35)),4,IF(AC35<>"",3,2))+IF(Z35<>"",1,0))) -> #VALUE! | AN35: =IF(M35="","",IF(M35<=70000,5,IF(M35<=85000,4,IF(M35<=100000,3,IF(M35<=120000,2,1))))) -> 2 | AO35: =IF(O35="","",IF(O35<=150,5,IF(O35<=200,4,IF(O35<=250,3,IF(O35<=300,2,1))))) -> 3 | AP35: =IF(B35="","",IF(AND(X35="확인",U35>0),5,IF(X35="확인",4,IF(AE35<>"",2,1)))) -> 1 | AQ35: 3 | AR35: 3 | AS35: =IF(B35="","",ROUND(AN35*Assumptions!$B$3+AO35*Assumptions!$B$4+AM35*Assumptions!$B$5+AP35*Assumptions!$B$6+AQ35*Assumptions!$B$7+AR35*Assumptions!$B$8,2)) -> #VALUE! | AT35: =IF(AS35="","",IF(AS35>=4.2,"A",IF(AS35>=3.4,"B","C"))) -> #VALUE! | AU35: =IF(AD35="","",IF(AD35<=25000000,"~2.5억",IF(AD35<=35000000,"2.5~3.5억",IF(AD35<=50000000,"3.5~5억","5억+")))) -> ~2.5억
A36: 49 | B36: 더청담 | C36: 강남구 | D36: 서울 강남구 도산대로 356 | E36: 서울특별시 | F36: 하우스 | G36: 밝은홀 | H36: 분리 | I36: 90 | J36: 1 | K36: 양식 | L36: 95000 | M36: 95000 | N36: 95000 | O36: 250 | P36: 1000 | Q36: 9500000 | R36: - | S36: - | T36: - | V36: =IF(AND(T36="",AB36>0),ROUND(AB36*10%,-4),T36) -> - | X36: 미확인 | Y36: https://map.naver.com/v5/search/더청담 | AC36: =IF(AND(L36>0,N36>0),L36*N36+IF(P36="",0,P36)+IF(Q36="",0,Q36)+IF(S36="",0,S36),"") -> #VALUE! | AD36: =IF(COUNTA(B36:AB36)=0,"",COUNTA(B36:AB36)-COUNTBLANK(B36:AB36)) -> 17 | AG36: 61.6 | AH36: 46.2 | AI36: 확인필요 | AJ36: =IF(OR(C36="강남구",C36="서초구",C36="송파구"),"강남권","비강남권") -> 강남권 | AK36: =IF(C36="강남구","강남",IF(C36="서초구","서초",IF(C36="송파구","송파",IF(C36="영등포구","영등포",IF(C36="마포구","마포","기타"))))) -> 강남 | AM36: =IF(B36="","",MIN(5,IF(ISNUMBER(SEARCH("역",AC36)),4,IF(AC36<>"",3,2))+IF(Z36<>"",1,0))) -> #VALUE! | AN36: =IF(M36="","",IF(M36<=70000,5,IF(M36<=85000,4,IF(M36<=100000,3,IF(M36<=120000,2,1))))) -> 3 | AO36: =IF(O36="","",IF(O36<=150,5,IF(O36<=200,4,IF(O36<=250,3,IF(O36<=300,2,1))))) -> 3 | AP36: =IF(B36="","",IF(AND(X36="확인",U36>0),5,IF(X36="확인",4,IF(AE36<>"",2,1)))) -> 1 | AQ36: 3 | AR36: 3 | AS36: =IF(B36="","",ROUND(AN36*Assumptions!$B$3+AO36*Assumptions!$B$4+AM36*Assumptions!$B$5+AP36*Assumptions!$B$6+AQ36*Assumptions!$B$7+AR36*Assumptions!$B$8,2)) -> #VALUE! | AT36: =IF(AS36="","",IF(AS36>=4.2,"A",IF(AS36>=3.4,"B","C"))) -> #VALUE! | AU36: =IF(AD36="","",IF(AD36<=25000000,"~2.5억",IF(AD36<=35000000,"2.5~3.5억",IF(AD36<=50000000,"3.5~5억","5억+")))) -> ~2.5억
A37: 49 | B37: 더청담 | C37: 강남구 | D37: 서울 강남구 도산대로 356 | E37: 서울특별시 | F37: 하우스 | G37: 밝은홀 | H37: 동시 | I37: 300 | J37: 1 | K37: 양식 | L37: 95000 | M37: 95000 | N37: 95000 | O37: 150 | P37: 200 | Q37: 11000000 | R37: - | S37: - | T37: - | V37: =IF(AND(T37="",AB37>0),ROUND(AB37*10%,-4),T37) -> - | X37: 미확인 | Y37: https://map.naver.com/v5/search/더청담 | AC37: =IF(AND(L37>0,N37>0),L37*N37+IF(P37="",0,P37)+IF(Q37="",0,Q37)+IF(S37="",0,S37),"") -> #VALUE! | AD37: =IF(COUNTA(B37:AB37)=0,"",COUNTA(B37:AB37)-COUNTBLANK(B37:AB37)) -> 17 | AG37: 61.6 | AH37: 46.2 | AI37: 확인필요 | AJ37: =IF(OR(C37="강남구",C37="서초구",C37="송파구"),"강남권","비강남권") -> 강남권 | AK37: =IF(C37="강남구","강남",IF(C37="서초구","서초",IF(C37="송파구","송파",IF(C37="영등포구","영등포",IF(C37="마포구","마포","기타"))))) -> 강남 | AM37: =IF(B37="","",MIN(5,IF(ISNUMBER(SEARCH("역",AC37)),4,IF(AC37<>"",3,2))+IF(Z37<>"",1,0))) -> #VALUE! | AN37: =IF(M37="","",IF(M37<=70000,5,IF(M37<=85000,4,IF(M37<=100000,3,IF(M37<=120000,2,1))))) -> 3 | AO37: =IF(O37="","",IF(O37<=150,5,IF(O37<=200,4,IF(O37<=250,3,IF(O37<=300,2,1))))) -> 5 | AP37: =IF(B37="","",IF(AND(X37="확인",U37>0),5,IF(X37="확인",4,IF(AE37<>"",2,1)))) -> 1 | AQ37: 3 | AR37: 3 | AS37: =IF(B37="","",ROUND(AN37*Assumptions!$B$3+AO37*Assumptions!$B$4+AM37*Assumptions!$B$5+AP37*Assumptions!$B$6+AQ37*Assumptions!$B$7+AR37*Assumptions!$B$8,2)) -> #VALUE! | AT37: =IF(AS37="","",IF(AS37>=4.2,"A",IF(AS37>=3.4,"B","C"))) -> #VALUE! | AU37: =IF(AD37="","",IF(AD37<=25000000,"~2.5억",IF(AD37<=35000000,"2.5~3.5억",IF(AD37<=50000000,"3.5~5억","5억+")))) -> ~2.5억
